Workbook
Name __VAR1: [1]Presentation!#REF!
Name __VAR2: [1]Presentation!#REF!
Name __VAR3: [1]Presentation!#REF!
Name __VAR4: [1]Presentation!#REF!
Name __VAR5: [1]Presentation!#REF!
Name __VAR6: [1]Presentation!#REF!
Name __VAR7: [1]Presentation!#REF!
Name __VAR8: [1]Presentation!#REF!
Name _VAR1: [1]Presentation!#REF!
Name _VAR1: [1]Presentation!#REF!
Name _VAR1: [1]Presentation!#REF!
Name _VAR2: [1]Presentation!#REF!
Name _VAR2: [1]Presentation!#REF!
Name _VAR2: [1]Presentation!#REF!
Name _VAR3: [1]Presentation!#REF!
Name _VAR3: [1]Presentation!#REF!
Name _VAR3: [1]Presentation!#REF!
Name _VAR4: [1]Presentation!#REF!
Name _VAR4: [1]Presentation!#REF!
Name _VAR4: [1]Presentation!#REF!
Name _VAR5: [1]Presentation!#REF!
Name _VAR5: [1]Presentation!#REF!
Name _VAR5: [1]Presentation!#REF!
Name _VAR6: [1]Presentation!#REF!
Name _VAR6: [1]Presentation!#REF!
Name _VAR6: [1]Presentation!#REF!
Name _VAR7: [1]Presentation!#REF!
Name _VAR7: [1]Presentation!#REF!
Name _VAR7: [1]Presentation!#REF!
Name _VAR8: [1]Presentation!#REF!
Name _VAR8: [1]Presentation!#REF!
Name _VAR8: [1]Presentation!#REF!
Name AN1PMIEGROUPE: #REF!
Name APMIEGROUPE2: '[1]T2 Actual N'!$B$134:$AL$151
Name B1OA060STEGROUPE: '[2]Budget N+1'!$A$191:$AC$208
Name base: [1]Presentation!#REF!
Name base: [1]Presentation!#REF!
Name base: [1]Presentation!#REF!
Name BCENTRALOA2: '[1]T2 Budget N'!$A$251:$H$268
Name BFRMPOA2: '[1]T2 Budget N'!$A$71:$U$88
Name BITA2: '[1]T2 Budget N'!$A$314:$J$332
Name BOA060STEGROUPE2: '[1]T2 Budget N'!$A$190:$AH$207
Name BOA061STEGROUPE2: '[1]T2 Budget N'!$A$221:$AH$238
Name BOAGROUPE2: '[1]T2 Budget N'!$A$11:$U$28
Name BPMIE2: '[1]T2 Budget N'!$C$130:$AL$147
Name BPROMOLUX2: '[1]T2 Budget N'!$A$346:$C$364
Name BSPOA2: '[1]T2 Budget N'!$A$101:$T$118
Name BSTEGROUPE2: '[1]T2 Budget N'!$A$41:$AH$58
Name DATE: [1]Presentation!#REF!
Name DATE: [1]Presentation!#REF!
Name DATE: [1]Presentation!#REF!
Name E1PMGBP: [3]GBP!$F$82:$I$92
Name EGBP: [3]GBP!$A$82:$D$92
Name EHDPMGROUP: '[3]Estimé N'!$A$162:$AE$179
Name ENCENTRALOA: #REF!
Name ENFRMPOA: #REF!
Name ENHDPMGROUP: '[3]Estimé précédent N'!$A$161:$AF$178
Name ENOAGROUPE: #REF!
Name ENSPOA: #REF!
Name ENSTEGROUPE: #REF!

Sheet 1. Business Lines (2)
B3: Code MAGNITUDE | C3: Code SOLARE | D3: English description
B4: OA020 | C4: PMA_8023 | D4: Consulting & Corporate Real Estate
B5: OA020O | C5: PMA_8047 | D5: Traker
B6: OA011E | C6: PMA_8026 | D6: CONSULTING - Debt Advisor
B7: OA024 | C7: PMA_8024 | D7: Rural Consultancy
B8: OA022 | C8: PMA_8025 | D8: Space consulting & Space Planning
B9: OA019O | C9: PMA_8038 | D9: Coordination Advisory
B10: OA011O | C10: NOT USED | D10: NOT USED
B11: OA011 | C11: PMA_8041 | D11: Investment
B12: OA010 | C12: PMA_8037 | D12: Letting & Sales
B13: OA023 | C13: PMA_8027 | D13: Residential Development & Planning
B14: OA017 | C14: PMA_8028 | D14: Residential Retail Sales/ Residential Agency
... B37: OA016 | C37: PMA_8007 | D37: Sales to Investors & Institutional

Sheet 2. Entities
B3: Code Magnitude | C3: Lib Magnitude | D3: Ccy | E3: Code SOLARE | F3: Lib SOLARE
B4: G-BE | C4: BNPP RE Belgium | D4: EUR | E4: EJ_21908 | F4: BNPP RE Belgium
B5: G-BE | C5: BNPP RE Belgium | D5: EUR | E5: EJ_47884 | F5: BNPP REIM Belgium
B6: G-DE | C6: BNPP RE Germany APM | D6: EUR | E6: EJ_21902 | F6: BNPPRE Holding GmbH
B7: G-DE | C7: BNPP RE Germany APM | D7: EUR | E7: EJ_21904 | F7: BNPPRE GmbH
B8: G-DE | C8: BNPP RE Germany APM | D8: EUR | E8: EJ_21905 | F8: BNPP REPM GmbH
B9: G-DE | C9: BNPP RE Germany APM | D9: EUR | E9: EJ_21906 | F9: BNPPRE Consult GmbH
B10: G-DEPROMO | C10: BNPP RE Germany Promotion | D10: EUR | E10: EJ_65631 | F10: BNP Paribas Real Estate Property Devlopment & Services
B11: G-REIMI | C11: BNPP REIM International | D11: EUR | E11: EJ_65631 | F11: BNP Paribas Real Estate Property Devlopment & Services
B12: G-REIMDE | C12: BNPP REIM Germany | D12: EUR | E12: EJ_58476 | F12: BNPP Real Estate Investment Management Germany GmbH
B13: G-IR | C13: BNPP RE Ireland | D13: EUR | E13: EJ_42444 | F13: BNPPRE APM Ireland
B14: G-ITAR | C14: BNPP RE Advisory Italy | D14: EUR | E14: EJ_40711 | F14: BNPPRE Advisory Italy
... B38: G-UKPROMO | C38: BNPP REPD UK | D38: GBP | E38: EJ_63264 | F38: REPD Parker Limited

Sheet Réalisé Vs Estimé
A1: SC=BNPPI-GEST
A2: CC=EUR
A3: FA sum AR002
A4: FL=F99 | E4: {AC=GFB001}+{AC=GFB002}+{AC=GFB004}+{AC=GFB008}+{AC=GFB009}+{AC=GFB003} | G4: {AC=GFB001}+{AC=GFB002}+{AC=GFB004}+{AC=GFB008}+{AC=GFB009}+{AC=GFB003} | K4: {AC=GFB005}+{AC=GFB006}+{AC=GFB110}+{AC=GFB111}+{AC=GFB112}+{AC=GFB120}+{AC=GFB121}+{AC=GFB122}+{AC=GFB100}+{AC=GFB101}+{AC=GFB102}+{AC=GFB130}+{AC=GFB131}+{AC=GFB132} | M4: {AC=GFB005}+{AC=GFB006}+{AC=GFB110}+{AC=GFB111}+{AC=GFB112}+{AC=GFB120}+{AC=GFB121}+{AC=GFB122}+{AC=GFB100}+{AC=GFB101}+{AC=GFB102}+{AC=GFB130}+{AC=GFB131}+{AC=GFB132} | Q4: AC sum RGFB | S4: AC sum RGFB | W4: AC sum RGFB | Y4: AC sum RGFB | AC4: AC sum RGFB | AE4: AC sum RGFB | AI4: AC sum RGFB | AK4: AC sum RGFB | AO4: AC sum RGFB | AQ4: AC sum RGFB | BA4: AC sum RGFB | BB4: AC sum RGFB | BC4: AC sum RGFB | BG4: =+AO4 -> AC sum RGFB | BI4: =+AQ4 -> AC sum RGFB | BN4: =+BG4 -> AC sum RGFB | BO4: =+BH4 -> 0 | BP4: =+BI4 -> AC sum RGFB
E5: CA=A | G5: CA=E | K5: =E5 -> CA=A | L5: =K5 -> CA=A | M5: =G5 -> CA=E | N5: =M5 -> CA=E | Q5: =E5 -> CA=A | R5: =Q5 -> CA=A | S5: =G5 -> CA=E | T5: =S5 -> CA=E | W5: =L5 -> CA=A | X5: =W5 -> CA=A | Y5: =N5 -> CA=E | Z5: =Y5 -> CA=E | AC5: =R5 -> CA=A | AD5: =AC5 -> CA=A | AE5: =T5 -> CA=E | AF5: =AE5 -> CA=E | AI5: =W5 -> CA=A | AJ5: =AI5 -> CA=A | AK5: =Y5 -> CA=E | AL5: =AK5 -> CA=E | AO5: =AC5 -> CA=A | AP5: =AO5 -> CA=A | AQ5: =AE5 -> CA=E | AR5: =AQ5 -> CA=E | BA5: =AO5 -> CA=A | BB5: =BA5 -> CA=A | BC5: =AQ5 -> CA=E | BD5: =BC5 -> CA=E | BG5: =+AO5 -> CA=A | BH5: =BG5 -> CA=A | BI5: =+AQ5 -> CA=E | BJ5: =BI5 -> CA=E | BN5: =+BG5 -> CA=A | BO5: =+BH5 -> CA=A | BP5: =+BI5 -> CA=E | BQ5: =BP5 -> CA=E
E6: DP=2026.03 | F6: DP=2024.13 | G6: DP=2026.03 | K6: =E6 -> DP=2026.03 | L6: =K6 -> DP=2026.03 | M6: =G6 -> DP=2026.03 | N6: =M6 -> DP=2026.03 | Q6: =E6 -> DP=2026.03 | R6: =Q6 -> DP=2026.03 | S6: =G6 -> DP=2026.03 | T6: =S6 -> DP=2026.03 | W6: =L6 -> DP=2026.03 | X6: =W6 -> DP=2026.03 | Y6: =N6 -> DP=2026.03 | Z6: =Y6 -> DP=2026.03 | AC6: =R6 -> DP=2026.03 | AD6: =AC6 -> DP=2026.03 | AE6: =T6 -> DP=2026.03 | AF6: =AE6 -> DP=2026.03 | AI6: =W6 -> DP=2026.03 | AJ6: =AI6 -> DP=2026.03 | AK6: =Y6 -> DP=2026.03 | AL6: =AK6 -> DP=2026.03 | AO6: =AC6 -> DP=2026.03 | AP6: =AO6 -> DP=2026.03 | AQ6: =AE6 -> DP=2026.03 | AR6: =AQ6 -> DP=2026.03 | BA6: =AO6 -> DP=2026.03 | BB6: =BA6 -> DP=2026.03 | BC6: =AQ6 -> DP=2026.03 | BD6: =BC6 -> DP=2026.03 | BG6: =+AO6 -> DP=2026.03 | BH6: =BG6 -> DP=2026.03 | BI6: =+AQ6 -> DP=2026.03 | BJ6: =BI6 -> DP=2026.03 | BN6: =+BG6 -> DP=2026.03 | BO6: =+BH6 -> DP=2026.03 | BP6: =+BI6 -> DP=2026.03 | BQ6: =BP6 -> DP=2026.03
E7: PE=2026.03 | F7: PE=2024.13 | G7: PE=2026.03 | K7: =E7 -> PE=2026.03 | L7: =K7 -> PE=2026.03 | M7: =G7 -> PE=2026.03 | N7: =M7 -> PE=2026.03 | Q7: =E7 -> PE=2026.03 | R7: =Q7 -> PE=2026.03 | S7: =G7 -> PE=2026.03 | T7: =S7 -> PE=2026.03 | W7: =L7 -> PE=2026.03 | X7: =W7 -> PE=2026.03 | Y7: =N7 -> PE=2026.03 | Z7: =Y7 -> PE=2026.03 | AC7: =R7 -> PE=2026.03 | AD7: =AC7 -> PE=2026.03 | AE7: =T7 -> PE=2026.03 | AF7: =AE7 -> PE=2026.03 | AI7: =W7 -> PE=2026.03 | AJ7: =AI7 -> PE=2026.03 | AK7: =Y7 -> PE=2026.03 | AL7: =AK7 -> PE=2026.03 | AO7: =AC7 -> PE=2026.03 | AP7: =AO7 -> PE=2026.03 | AQ7: =AE7 -> PE=2026.03 | AR7: =AQ7 -> PE=2026.03 | BA7: =AO7 -> PE=2026.03 | BB7: =BA7 -> PE=2026.03 | BC7: =AQ7 -> PE=2026.03 | BD7: =BC7 -> PE=2026.03 | BG7: =+AO7 -> PE=2026.03 | BH7: =BG7 -> PE=2026.03 | BI7: =+AQ7 -> PE=2026.03 | BJ7: =BI7 -> PE=2026.03 | BN7: =+BG7 -> PE=2026.03 | BO7: =+BH7 -> PE=2026.03 | BP7: =+BI7 -> PE=2026.03 | BQ7: =BP7 -> PE=2026.03
E8: =VLOOKUP([6]Présentation!$E$31,[6]Présentation!$B$93:$C$94,2,FALSE) -> AU sum GEST00 | G8: =VLOOKUP([6]Présentation!$E$31,[6]Présentation!$B$93:$C$94,2,FALSE) -> AU sum GEST00 | K8: =E8 -> AU sum GEST00 | L8: =K8 -> AU sum GEST00 | M8: =G8 -> AU sum GEST00 | N8: =M8 -> AU sum GEST00 | Q8: =E8 -> AU sum GEST00 | R8: =Q8 -> AU sum GEST00 | S8: =G8 -> AU sum GEST00 | T8: =S8 -> AU sum GEST00 | W8: =L8 -> AU sum GEST00 | X8: =W8 -> AU sum GEST00 | Y8: =N8 -> AU sum GEST00 | Z8: =Y8 -> AU sum GEST00 | AC8: =R8 -> AU sum GEST00 | AD8: =AC8 -> AU sum GEST00 | AE8: =T8 -> AU sum GEST00 | AF8: =AE8 -> AU sum GEST00 | AI8: =W8 -> AU sum GEST00 | AJ8: =AI8 -> AU sum GEST00 | AK8: =Y8 -> AU sum GEST00 | AL8: =AK8 -> AU sum GEST00 | AO8: =AC8 -> AU sum GEST00 | AP8: =AO8 -> AU sum GEST00 | AQ8: =AE8 -> AU sum GEST00 | AR8: =AQ8 -> AU sum GEST00 | BA8: =AO8 -> AU sum GEST00 | BB8: =BA8 -> AU sum GEST00 | BC8: =AQ8 -> AU sum GEST00 | BD8: =BC8 -> AU sum GEST00 | BG8: =+AO8 -> AU sum GEST00 | BH8: =BG8 -> AU sum GEST00 | BI8: =+AQ8 -> AU sum GEST00 | BJ8: =BI8 -> AU sum GEST00 | BN8: =+BG8 -> AU sum GEST00 | BO8: =+BH8 -> AU sum GEST00 | BP8: =+BI8 -> AU sum GEST00 | BQ8: =BP8 -> AU sum GEST00
E9: =VLOOKUP([6]Présentation!$E$38,[6]Présentation!$B$60:$C$61,2,FALSE) -> VA=RECOMPO | G9: =VLOOKUP([6]Présentation!$E$38,[6]Présentation!$B$60:$C$61,2,FALSE) -> VA=RECOMPO | K9: =E9 -> VA=RECOMPO | L9: =K9 -> VA=RECOMPO | M9: =G9 -> VA=RECOMPO | N9: =M9 -> VA=RECOMPO | Q9: =E9 -> VA=RECOMPO | R9: =Q9 -> VA=RECOMPO | S9: =G9 -> VA=RECOMPO | T9: =S9 -> VA=RECOMPO | W9: =L9 -> VA=RECOMPO | X9: =W9 -> VA=RECOMPO | Y9: =N9 -> VA=RECOMPO | Z9: =Y9 -> VA=RECOMPO | AC9: =R9 -> VA=RECOMPO | AD9: =AC9 -> VA=RECOMPO | AE9: =T9 -> VA=RECOMPO | AF9: =AE9 -> VA=RECOMPO | AI9: =W9 -> VA=RECOMPO | AJ9: =AI9 -> VA=RECOMPO | AK9: =Y9 -> VA=RECOMPO | AL9: =AK9 -> VA=RECOMPO | AO9: =AC9 -> VA=RECOMPO | AP9: =AO9 -> VA=RECOMPO | AQ9: =AE9 -> VA=RECOMPO | AR9: =AQ9 -> VA=RECOMPO | BA9: =AO9 -> VA=RECOMPO | BB9: =BA9 -> VA=RECOMPO | BC9: =AQ9 -> VA=RECOMPO | BD9: =BC9 -> VA=RECOMPO | BG9: =+AO9 -> VA=RECOMPO | BH9: =BG9 -> VA=RECOMPO | BI9: =+AQ9 -> VA=RECOMPO | BJ9: =BI9 -> VA=RECOMPO | BN9: =+BG9 -> VA=RECOMPO | BO9: =+BH9 -> VA=RECOMPO | BP9: =+BI9 -> VA=RECOMPO | BQ9: =BP9 -> VA=RECOMPO
E10: {AC=GPNBTOT}+{AC=GR5400} | G10: {AC=GPNBTOT}+{AC=GR5400} | K10: AC=GFDGT | L10: AC=GFDGHT | M10: AC=GFDGT | N10: AC=GFDGHT | Q10: AC=GRNAI | R10: AC=GS0911 | S10: AC=GRNAI | T10: AC=GS0911 | W10: AC=GRITC001 | X10: =W10 -> AC=GRITC001 | Y10: =W10 -> AC=GRITC001 | Z10: =Y10 -> AC=GRITC001 | AC10: AC=GRITC002 | AD10: =AC10 -> AC=GRITC002 | AE10: =AC10 -> AC=GRITC002 | AF10: =AE10 -> AC=GRITC002 | AI10: {AC=GRITC003}+{AC=GRITC004}+{AC=GRITC005} | AJ10: =AI10 -> {AC=GRITC003}+{AC=GRITC004}+{AC=GRITC005} | AK10: =AI10 -> {AC=GRITC003}+{AC=GRITC004}+{AC=GRITC005} | AL10: =AK10 -> {AC=GRITC003}+{AC=GRITC004}+{AC=GRITC005} | AO10: {AC=GFB130}+{AC=GFB110} | AP10: =AO10 -> {AC=GFB130}+{AC=GFB110} | AQ10: =AO10 -> {AC=GFB130}+{AC=GFB110} | AR10: =AQ10 -> {AC=GFB130}+{AC=GFB110} | BA10: AC=GRNAI | BB10: AC=GS0911 | BC10: AC=GRNAI | BD10: AC=GS0911 | BG10: {AC=GFB130} | BI10: {AC=GFB130} | BN10: {AC=GFB110} | BO10: =BN10 -> {AC=GFB110} | BP10: =+BN10 -> {AC=GFB110} | BQ10: =BP10 -> {AC=GFB110}
D11: m€ | E11: =CHOOSE([6]Traduction!$A$2,[6]Traduction!$A94,[6]Traduction!$B94) -> Net Banking Income + Result of Co-Dev JVs | K11: =CHOOSE([6]Traduction!$A$2,[6]Traduction!$A40,[6]Traduction!$B40) -> General Operating Expenses | Q11: =CHOOSE([6]Traduction!$A$2,[6]Traduction!$A41,[6]Traduction!$B41) -> Pre-Tax Income | W11: SLA Plateforms | Z11: =Y11 -> 0 | AC11: SLA Steering IM | AF11: =AE11 -> 0 | AI11: SLA IIC+Retail+Logistics | AL11: =AK11 -> 0 | AO11: Management Fees + BNPP SA rebilling | AR11: =AQ11 -> 0 | AU11: Total Internal SLA + MF + BNPP SA Rebilling | BG11: Management Fees + BNPP SA rebilling | BJ11: =BI11 -> 0 | BN11: Management Fees + BNPP SA rebilling | BQ11: =BP11 -> 0
A13: OA sum (TYPE-OA=OA06)
D14: Actual N vs Estimate-1 at perimeter & Historical conversion rate | E14: Actual Q1 2026 | G14: Estimate March Q1 2026 | I14: Variances | K14: =E14 -> Actual Q1 2026 | M14: =G14 -> Estimate March Q1 2026 | O14: =I14 -> Variances | Q14: =E14 -> Actual Q1 2026 | S14: =G14 -> Estimate March Q1 2026 | U14: =I14 -> Variances | W14: =E14 -> Actual Q1 2026 | Y14: =G14 -> Estimate March Q1 2026 | AA14: =I14 -> Variances | AC14: =W14 -> Actual Q1 2026 | AE14: =Y14 -> Estimate March Q1 2026 | AG14: =AA14 -> Variances | AI14: =W14 -> Actual Q1 2026 | AK14: =Y14 -> Estimate March Q1 2026 | AM14: =AA14 -> Variances | AO14: =AC14 -> Actual Q1 2026 | AQ14: =AE14 -> Estimate March Q1 2026 | AS14: =AG14 -> Variances | AU14: =AI14 -> Actual Q1 2026 | AW14: =AK14 -> Estimate March Q1 2026 | AY14: =AM14 -> Variances | BA14: =AO14 -> Actual Q1 2026 | BC14: =AQ14 -> Estimate March Q1 2026 | BE14: =AS14 & " excl. Management Fees and equivalent " -> Variances excl. Management Fees and equivalent | BG14: =AU14 -> Actual Q1 2026 | BI14: =AW14 -> Estimate March Q1 2026 | BK14: =AY14 -> Variances | BN14: =BB14 -> 0 | BP14: =BD14 -> 0 | BR14: =BF14 -> 0
E15: Standalone | G15: Standalone | K15: =VLOOKUP([6]Présentation!$D$30,[6]Présentation!#REF!,2,FALSE) -> #REF! | M15: =VLOOKUP([6]Présentation!$D$30,[6]Présentation!#REF!,8,FALSE) -> #REF! | Q15: Standalone | S15: Standalone | W15: Standalone | Y15: Standalone | AC15: Standalone | AE15: Standalone | AI15: Standalone | AK15: Standalone | AO15: Standalone | AQ15: Standalone | AU15: Standalone | AW15: Standalone | BA15: Standalone | BC15: Standalone | BE15: Σ | BG15: Standalone | BI15: Standalone | BN15: Standalone | BP15: Standalone
D17: Property Development | E17: =E18+E19+E25 -> #NAME? | G17: =G18+G19+G25 -> #NAME? | I17: =E17-G17 -> #NAME? | K17: =K18+K19+K25 -> #NAME? | M17: =M18+M19+M25 -> #NAME? | O17: =K17-M17 -> #NAME? | Q17: =Q18+Q19+Q25 -> #NAME? | S17: =S18+S19+S25 -> #NAME? | U17: =Q17-S17 -> #NAME? | W17: =SUM(W18:W33)-W31 -> #NAME? | Y17: =SUM(Y18:Y33)-Y31 -> #NAME? | AA17: =W17-Y17 -> #NAME? | AC17: =SUM(AC18:AC33)-AC31 -> #NAME? | AE17: =SUM(AE18:AE33)-AE31 -> #NAME? | AG17: =AC17-AE17 -> #NAME? | AI17: =SUM(AI18:AI33)-AI31 -> #NAME? | AK17: =SUM(AK18:AK33)-AK31 -> #NAME? | AM17: =AI17-AK17 -> #NAME? | AO17: =SUM(AO18:AO33)-AO31 -> #NAME? | AQ17: =SUM(AQ18:AQ33)-AQ31 -> #NAME? | AS17: =AO17-AQ17 -> #NAME? | AU17: =W17+AC17+AI17+AO17 -> #NAME? | AW17: =Y17+AE17+AK17+AQ17 -> #NAME? | AY17: =AU17-AW17 -> #NAME? | BA17: =+Q17-AO17 -> #NAME? | BC17: =+S17-AQ17 -> #NAME? | BE17: =BA17-BC17 -> #NAME? | BG17: =SUM(BG18:BG33)-BG31 -> #NAME? | BI17: =SUM(BI18:BI33)-BI31 -> #NAME? | BK17: =BG17-BI17 -> #NAME? | BN17: =SUM(BN18:BN33)-BN31 -> #NAME? | BP17: =SUM(BP18:BP33)-BP31 -> #NAME? | BR17: =BN17-BP17 -> #NAME?
A18: {OA=OA040}+{OA=OA041} | B18: {RU=G-CENTRAL}+{RU=P-CENTRAL} | C18: FR | D18: G-central | E18: =_xll.GetCtData("CO-AMOUNT","CONS-AMOUNT",$A$1:$A$4,$A18:$B18,E$5:E$10,"#") -> #NAME? | G18: =_xll.GetCtData("CO-AMOUNT","CONS-AMOUNT",$A$1:$A$4,$A18:$B18,G$5:G$10,"#") -> #NAME? | I18: =E18-G18 -> #NAME? | K18: =_xll.GetCtData("CO-AMOUNT","CONS-AMOUNT",$A$1:$A$4,$A18:$B18,K$5:K$10,"#") -> #NAME? | M18: =_xll.GetCtData("CO-AMOUNT","CONS-AMOUNT",$A$1:$A$4,$A18:$B18,M$5:M$10,"#") -> #NAME? | O18: =K18-M18 -> #NAME? | Q18: =_xll.GetCtData("CO-AMOUNT","CONS-AMOUNT",$A$1:$A$4,$A18:$B18,Q$5:Q$10,"#") -> #NAME? | S18: =_xll.GetCtData("CO-AMOUNT","CONS-AMOUNT",$A$1:$A$4,$A18:$B18,S$5:S$10,"#") -> #NAME? | U18: =Q18-S18 -> #NAME? | W18: =_xll.GetCtData("CO-AMOUNT","CONS-AMOUNT",$A$1:$A$4,$A18:$B18,W$5:W$10,"#") -> #NAME? | Y18: =_xll.GetCtData("CO-AMOUNT","CONS-AMOUNT",$A$1:$A$4,$A18:$B18,Y$5:Y$10,"#") -> #NAME? | AA18: =W18-Y18 -> #NAME? | AC18: =_xll.GetCtData("CO-AMOUNT","CONS-AMOUNT",$A$1:$A$4,$A18:$B18,AC$5:AC$10,"#") -> #NAME? | AE18: =_xll.GetCtData("CO-AMOUNT","CONS-AMOUNT",$A$1:$A$4,$A18:$B18,AE$5:AE$10,"#") -> #NAME? | AG18: =AC18-AE18 -> #NAME? | AI18: =_xll.GetCtData("CO-AMOUNT","CONS-AMOUNT",$A$1:$A$4,$A18:$B18,AI$5:AI$10,"#") -> #NAME? | AK18: =_xll.GetCtData("CO-AMOUNT","CONS-AMOUNT",$A$1:$A$4,$A18:$B18,AK$5:AK$10,"#") -> #NAME? | AM18: =AI18-AK18 -> #NAME? | AO18: =_xll.GetCtData("CO-AMOUNT","CONS-AMOUNT",$A$1:$A$4,$A18:$B18,AO$5:AO$10,"#") -> #NAME? | AQ18: =_xll.GetCtData("CO-AMOUNT","CONS-AMOUNT",$A$1:$A$4,$A18:$B18,AQ$5:AQ$10,"#") -> #NAME? | AS18: =AO18-AQ18 -> #NAME? | AU18: =W18+AC18+AI18+AO18 -> #NAME? | AW18: =Y18+AE18+AK18+AQ18 -> #NAME? | AY18: =AU18-AW18 -> #NAME? | BA18: =+Q18-AO18 -> #NAME? | BC18: =+S18-AQ18 -> #NAME? | BE18: =BA18-BC18 -> #NAME? | BG18: =_xll.GetCtData("CO-AMOUNT","CONS-AMOUNT",$A$1:$A$4,$A18:$B18,BG$5:BG$10,"#") -> #NAME? | BI18: =_xll.GetCtData("CO-AMOUNT","CONS-AMOUNT",$A$1:$A$4,$A18:$B18,BI$5:BI$10,"#") -> #NAME? | BK18: =BG18-BI18 -> #NAME? | BN18: =_xll.GetCtData("CO-AMOUNT","CONS-AMOUNT",$A$1:$A$4,$A18:$B18,BN$5:BN$10,"#") -> #NAME? | BP18: =_xll.GetCtData("CO-AMOUNT","CONS-AMOUNT",$A$1:$A$4,$A18:$B18,BP$5:BP$10,"#") -> #NAME? | BR18: =BN18-BP18 -> #NAME?
D19: =CHOOSE([6]Traduction!$A$2,[6]Traduction!$A45,[6]Traduction!$B45) -> o/w France | E19: =E22+E21+E20 -> #NAME? | G19: =G22+G21+G20 -> #NAME? | I19: =E19-G19 -> #NAME? | K19: =K22+K21+K20 -> #NAME? | M19: =M22+M21+M20 -> #NAME? | O19: =K19-M19 -> #NAME? | Q19: =Q22+Q21+Q20 -> #NAME? | S19: =S22+S21+S20 -> #NAME? | U19: =Q19-S19 -> #NAME? | W19: =_xll.GetCtData("CO-AMOUNT","CONS-AMOUNT",$A$1:$A$4,$A19:$B19,W$5:W$10,"#-119,137061911572") -> #NAME? | Y19: =_xll.GetCtData("CO-AMOUNT","CONS-AMOUNT",$A$1:$A$4,$A19:$B19,Y$5:Y$10,"#139,303394874322") -> #NAME? | AA19: =W19-Y19 -> #NAME? | AC19: =_xll.GetCtData("CO-AMOUNT","CONS-AMOUNT",$A$1:$A$4,$A19:$B19,AC$5:AC$10,"#22,98") -> #NAME? | AE19: =_xll.GetCtData("CO-AMOUNT","CONS-AMOUNT",$A$1:$A$4,$A19:$B19,AE$5:AE$10,"#7,27000000000001") -> #NAME? | AG19: =AC19-AE19 -> #NAME? | AI19: =_xll.GetCtData("CO-AMOUNT","CONS-AMOUNT",$A$1:$A$4,$A19:$B19,AI$5:AI$10,"#-65,1913655499592") -> #NAME? | AK19: =_xll.GetCtData("CO-AMOUNT","CONS-AMOUNT",$A$1:$A$4,$A19:$B19,AK$5:AK$10,"#418,511442896423") -> #NAME? | AM19: =AI19-AK19 -> #NAME? | AO19: =_xll.GetCtData("CO-AMOUNT","CONS-AMOUNT",$A$1:$A$4,$A19:$B19,AO$5:AO$10,"#-12821,1653475363") -> #NAME? | AQ19: =_xll.GetCtData("CO-AMOUNT","CONS-AMOUNT",$A$1:$A$4,$A19:$B19,AQ$5:AQ$10,"#-9611,83172873421") -> #NAME? | AS19: =AO19-AQ19 -> #NAME? | AU19: =W19+AC19+AI19+AO19 -> #NAME? | AW19: =Y19+AE19+AK19+AQ19 -> #NAME? | AY19: =AU19-AW19 -> #NAME? | BA19: =+Q19-AO19 -> #NAME? | BC19: =+S19-AQ19 -> #NAME? | BE19: =BA19-BC19 -> #NAME? | BG19: =_xll.GetCtData("CO-AMOUNT","CONS-AMOUNT",$A$1:$A$4,$A19:$B19,BG$5:BG$10,"#-6631,80636538518") -> #NAME? | BI19: =_xll.GetCtData("CO-AMOUNT","CONS-AMOUNT",$A$1:$A$4,$A19:$B19,BI$5:BI$10,"#-4370,58368251045") -> #NAME? | BK19: =BG19-BI19 -> #NAME? | BN19: =_xll.GetCtData("CO-AMOUNT","CONS-AMOUNT",$A$1:$A$4,$A19:$B19,BN$5:BN$10,"#-6189,3589821511") -> #NAME? | BP19: =_xll.GetCtData("CO-AMOUNT","CONS-AMOUNT",$A$1:$A$4,$A19:$B19,BP$5:BP$10,"#-5241,24804622376") -> #NAME? | BR19: =BN19-BP19 -> #NAME?
A20: {OA=OA040}+{OA=OA041} | B20: {RU=G-FRMP}+{RU=P-FRMP}+{RU=G-FRAR}+{RU=P-FRAR} | C20: FR | D20: o/w Prop Dev Offices and Resid | E20: =_xll.GetCtData("CO-AMOUNT","CONS-AMOUNT",$A$1:$A$4,$A20:$B20,E$5:E$10,"#-14399,59") -> #NAME? | G20: =_xll.GetCtData("CO-AMOUNT","CONS-AMOUNT",$A$1:$A$4,$A20:$B20,G$5:G$10,"#-14951,9") -> #NAME? | I20: =E20-G20 -> #NAME? | K20: =_xll.GetCtData("CO-AMOUNT","CONS-AMOUNT",$A$1:$A$4,$A20:$B20,K$5:K$10,"#-13734,963") -> #NAME? | M20: =_xll.GetCtData("CO-AMOUNT","CONS-AMOUNT",$A$1:$A$4,$A20:$B20,M$5:M$10,"#-14506,73") -> #NAME? | O20: =K20-M20 -> #NAME? | Q20: =_xll.GetCtData("CO-AMOUNT","CONS-AMOUNT",$A$1:$A$4,$A20:$B20,Q$5:Q$10,"#-28134,553") -> #NAME? | S20: =_xll.GetCtData("CO-AMOUNT","CONS-AMOUNT",$A$1:$A$4,$A20:$B20,S$5:S$10,"#-29458,63") -> #NAME? | U20: =Q20-S20 -> #NAME?
A21: OA=OA015 | B21: {RU=G-FRMP}+{RU=P-FRMP} | C21: FR | D21: o/w Residential sales | E21: =_xll.GetCtData("CO-AMOUNT","CONS-AMOUNT",$A$1:$A$4,$A21:$B21,E$5:E$10,"#") -> #NAME? | G21: =_xll.GetCtData("CO-AMOUNT","CONS-AMOUNT",$A$1:$A$4,$A21:$B21,G$5:G$10,"#") -> #NAME? | I21: =E21-G21 -> #NAME? | K21: =_xll.GetCtData("CO-AMOUNT","CONS-AMOUNT",$A$1:$A$4,$A21:$B21,K$5:K$10,"#") -> #NAME? | M21: =_xll.GetCtData("CO-AMOUNT","CONS-AMOUNT",$A$1:$A$4,$A21:$B21,M$5:M$10,"#") -> #NAME? | O21: =K21-M21 -> #NAME? | Q21: =_xll.GetCtData("CO-AMOUNT","CONS-AMOUNT",$A$1:$A$4,$A21:$B21,Q$5:Q$10,"#") -> #NAME? | S21: =_xll.GetCtData("CO-AMOUNT","CONS-AMOUNT",$A$1:$A$4,$A21:$B21,S$5:S$10,"#") -> #NAME? | U21: =Q21-S21 -> #NAME?
A22: OA sum AR021 | B22: {RU=G-FRMP}+{RU=P-FRMP} | C22: FR | D22: o/w Serviced Residences | E22: =_xll.GetCtData("CO-AMOUNT","CONS-AMOUNT",$A$1:$A$4,$A22:$B22,E$5:E$10,"#1714,35") -> #NAME? | G22: =_xll.GetCtData("CO-AMOUNT","CONS-AMOUNT",$A$1:$A$4,$A22:$B22,G$5:G$10,"#1485,056") -> #NAME? | I22: =E22-G22 -> #NAME? | K22: =_xll.GetCtData("CO-AMOUNT","CONS-AMOUNT",$A$1:$A$4,$A22:$B22,K$5:K$10,"#-1893,148") -> #NAME? | M22: =_xll.GetCtData("CO-AMOUNT","CONS-AMOUNT",$A$1:$A$4,$A22:$B22,M$5:M$10,"#-2067,487") -> #NAME? | O22: =K22-M22 -> #NAME? | Q22: =_xll.GetCtData("CO-AMOUNT","CONS-AMOUNT",$A$1:$A$4,$A22:$B22,Q$5:Q$10,"#-226,346000000001") -> #NAME? | S22: =_xll.GetCtData("CO-AMOUNT","CONS-AMOUNT",$A$1:$A$4,$A22:$B22,S$5:S$10,"#-596,373999999999") -> #NAME? | U22: =Q22-S22 -> #NAME?
A23: OA=OA036 | B23: {RU=G-FRMP}+{RU=P-FRMP} | C23: FR | D23: o/w Students Residences | E23: =_xll.GetCtData("CO-AMOUNT","CONS-AMOUNT",$A$1:$A$4,$A23:$B23,E$5:E$10,"#2620,14") -> #NAME? | G23: =_xll.GetCtData("CO-AMOUNT","CONS-AMOUNT",$A$1:$A$4,$A23:$B23,G$5:G$10,"#2458,496") -> #NAME? | I23: =E23-G23 -> #NAME? | K23: =_xll.GetCtData("CO-AMOUNT","CONS-AMOUNT",$A$1:$A$4,$A23:$B23,K$5:K$10,"#-1440,992") -> #NAME? | M23: =_xll.GetCtData("CO-AMOUNT","CONS-AMOUNT",$A$1:$A$4,$A23:$B23,M$5:M$10,"#-1562,699") -> #NAME? | O23: =K23-M23 -> #NAME? | Q23: =_xll.GetCtData("CO-AMOUNT","CONS-AMOUNT",$A$1:$A$4,$A23:$B23,Q$5:Q$10,"#1121,182") -> #NAME? | S23: =_xll.GetCtData("CO-AMOUNT","CONS-AMOUNT",$A$1:$A$4,$A23:$B23,S$5:S$10,"#870,797000000001") -> #NAME? | U23: =Q23-S23 -> #NAME?
A24: OA=OA037 | B24: {RU=G-FRMP}+{RU=P-FRMP} | C24: FR | D24: o/w Business Travellers Residences | E24: =_xll.GetCtData("CO-AMOUNT","CONS-AMOUNT",$A$1:$A$4,$A24:$B24,E$5:E$10,"#-905,79") -> #NAME? | G24: =_xll.GetCtData("CO-AMOUNT","CONS-AMOUNT",$A$1:$A$4,$A24:$B24,G$5:G$10,"#-973,44") -> #NAME? | I24: =E24-G24 -> #NAME? | K24: =_xll.GetCtData("CO-AMOUNT","CONS-AMOUNT",$A$1:$A$4,$A24:$B24,K$5:K$10,"#-452,156") -> #NAME? | M24: =_xll.GetCtData("CO-AMOUNT","CONS-AMOUNT",$A$1:$A$4,$A24:$B24,M$5:M$10,"#-504,788") -> #NAME? | O24: =K24-M24 -> #NAME? | Q24: =_xll.GetCtData("CO-AMOUNT","CONS-AMOUNT",$A$1:$A$4,$A24:$B24,Q$5:Q$10,"#-1347,528") -> #NAME? | S24: =_xll.GetCtData("CO-AMOUNT","CONS-AMOUNT",$A$1:$A$4,$A24:$B24,S$5:S$10,"#-1467,171") -> #NAME? | U24: =Q24-S24 -> #NAME?
D25: o/w International | E25: =E26+E27+E28+E29+E30+E32+E33 -> #NAME? | G25: =G26+G27+G28+G29+G30+G32+G33 -> #NAME? | I25: =E25-G25 -> #NAME? | K25: =K26+K27+K28+K29+K30+K32+K33 -> #NAME? | M25: =M26+M27+M28+M29+M30+M32+M33 -> #NAME? | O25: =K25-M25 -> #NAME? | Q25: =Q26+Q27+Q28+Q29+Q30+Q32+Q33 -> #NAME? | S25: =S26+S27+S28+S29+S30+S32+S33 -> #NAME? | U25: =Q25-S25 -> #NAME?
A26: OA sum AR028 | B26: RU sum AF026 | C26: ITA | D26: =CHOOSE([6]Traduction!$A$2,[6]Traduction!$A46,[6]Traduction!$B46) -> o/w Italy | E26: =_xll.GetCtData("CO-AMOUNT","CONS-AMOUNT",$A$1:$A$4,$A26:$B26,E$5:E$10,"#-88,982") -> #NAME? | G26: =_xll.GetCtData("CO-AMOUNT","CONS-AMOUNT",$A$1:$A$4,$A26:$B26,G$5:G$10,"#-88,772") -> #NAME? | I26: =E26-G26 -> #NAME? | K26: =_xll.GetCtData("CO-AMOUNT","CONS-AMOUNT",$A$1:$A$4,$A26:$B26,K$5:K$10,"#-67,413") -> #NAME? | M26: =_xll.GetCtData("CO-AMOUNT","CONS-AMOUNT",$A$1:$A$4,$A26:$B26,M$5:M$10,"#-60,617") -> #NAME? | O26: =K26-M26 -> #NAME? | Q26: =_xll.GetCtData("CO-AMOUNT","CONS-AMOUNT",$A$1:$A$4,$A26:$B26,Q$5:Q$10,"#-156,395") -> #NAME? | S26: =_xll.GetCtData("CO-AMOUNT","CONS-AMOUNT",$A$1:$A$4,$A26:$B26,S$5:S$10,"#-149,389") -> #NAME? | U26: =Q26-S26 -> #NAME? | W26: =_xll.GetCtData("CO-AMOUNT","CONS-AMOUNT",$A$1:$A$4,$A26:$B26,W$5:W$10,"#") -> #NAME? | Y26: =_xll.GetCtData("CO-AMOUNT","CONS-AMOUNT",$A$1:$A$4,$A26:$B26,Y$5:Y$10,"#") -> #NAME? | AA26: =W26-Y26 -> #NAME? | AC26: =_xll.GetCtData("CO-AMOUNT","CONS-AMOUNT",$A$1:$A$4,$A26:$B26,AC$5:AC$10,"#-1,438") -> #NAME? | AE26: =_xll.GetCtData("CO-AMOUNT","CONS-AMOUNT",$A$1:$A$4,$A26:$B26,AE$5:AE$10,"#-1,5") -> #NAME? | AG26: =AC26-AE26 -> #NAME? | AI26: =_xll.GetCtData("CO-AMOUNT","CONS-AMOUNT",$A$1:$A$4,$A26:$B26,AI$5:AI$10,"#") -> #NAME? | AK26: =_xll.GetCtData("CO-AMOUNT","CONS-AMOUNT",$A$1:$A$4,$A26:$B26,AK$5:AK$10,"#") -> #NAME? | AM26: =AI26-AK26 -> #NAME? | AO26: =_xll.GetCtData("CO-AMOUNT","CONS-AMOUNT",$A$1:$A$4,$A26:$B26,AO$5:AO$10,"#") -> #NAME? | AQ26: =_xll.GetCtData("CO-AMOUNT","CONS-AMOUNT",$A$1:$A$4,$A26:$B26,AQ$5:AQ$10,"#") -> #NAME? | AS26: =AO26-AQ26 -> #NAME? | AU26: =W26+AC26+AI26+AO26 -> #NAME? | AW26: =Y26+AE26+AK26+AQ26 -> #NAME? | AY26: =AU26-AW26 -> #NAME? | BA26: =+Q26-AO26 -> #NAME? | BC26: =+S26-AQ26 -> #NAME? | BE26: =BA26-BC26 -> #NAME? | BG26: =_xll.GetCtData("CO-AMOUNT","CONS-AMOUNT",$A$1:$A$4,$A26:$B26,BG$5:BG$10,"#") -> #NAME? | BI26: =_xll.GetCtData("CO-AMOUNT","CONS-AMOUNT",$A$1:$A$4,$A26:$B26,BI$5:BI$10,"#") -> #NAME? | BK26: =BG26-BI26 -> #NAME? | BN26: =_xll.GetCtData("CO-AMOUNT","CONS-AMOUNT",$A$1:$A$4,$A26:$B26,BN$5:BN$10,"#") -> #NAME? | BP26: =_xll.GetCtData("CO-AMOUNT","CONS-AMOUNT",$A$1:$A$4,$A26:$B26,BP$5:BP$10,"#") -> #NAME? | BR26: =BN26-BP26 -> #NAME?
A27: OA=OA040 | B27: RU=G-SP | C27: ESP | D27: =CHOOSE([6]Traduction!$A$2,[6]Traduction!$A48,[6]Traduction!$B48) -> o/w Spain | E27: =_xll.GetCtData("CO-AMOUNT","CONS-AMOUNT",$A$1:$A$4,$A27:$B27,E$5:E$10,"#24,798") -> #NAME? | G27: =_xll.GetCtData("CO-AMOUNT","CONS-AMOUNT",$A$1:$A$4,$A27:$B27,G$5:G$10,"#28,693") -> #NAME? | I27: =E27-G27 -> #NAME? | K27: =_xll.GetCtData("CO-AMOUNT","CONS-AMOUNT",$A$1:$A$4,$A27:$B27,K$5:K$10,"#-10,801") -> #NAME? | M27: =_xll.GetCtData("CO-AMOUNT","CONS-AMOUNT",$A$1:$A$4,$A27:$B27,M$5:M$10,"#-14,025") -> #NAME? | O27: =K27-M27 -> #NAME? | Q27: =_xll.GetCtData("CO-AMOUNT","CONS-AMOUNT",$A$1:$A$4,$A27:$B27,Q$5:Q$10,"#13,997") -> #NAME? | S27: =_xll.GetCtData("CO-AMOUNT","CONS-AMOUNT",$A$1:$A$4,$A27:$B27,S$5:S$10,"#14,668") -> #NAME? | U27: =Q27-S27 -> #NAME? | W27: =_xll.GetCtData("CO-AMOUNT","CONS-AMOUNT",$A$1:$A$4,$A27:$B27,W$5:W$10,"#") -> #NAME? | Y27: =_xll.GetCtData("CO-AMOUNT","CONS-AMOUNT",$A$1:$A$4,$A27:$B27,Y$5:Y$10,"#") -> #NAME? | AA27: =W27-Y27 -> #NAME? | AC27: =_xll.GetCtData("CO-AMOUNT","CONS-AMOUNT",$A$1:$A$4,$A27:$B27,AC$5:AC$10,"#4,75") -> #NAME? | AE27: =_xll.GetCtData("CO-AMOUNT","CONS-AMOUNT",$A$1:$A$4,$A27:$B27,AE$5:AE$10,"#-6,67") -> #NAME? | AG27: =AC27-AE27 -> #NAME? | AI27: =_xll.GetCtData("CO-AMOUNT","CONS-AMOUNT",$A$1:$A$4,$A27:$B27,AI$5:AI$10,"#") -> #NAME? | AK27: =_xll.GetCtData("CO-AMOUNT","CONS-AMOUNT",$A$1:$A$4,$A27:$B27,AK$5:AK$10,"#") -> #NAME? | AM27: =AI27-AK27 -> #NAME? | AO27: =_xll.GetCtData("CO-AMOUNT","CONS-AMOUNT",$A$1:$A$4,$A27:$B27,AO$5:AO$10,"#") -> #NAME? | AQ27: =_xll.GetCtData("CO-AMOUNT","CONS-AMOUNT",$A$1:$A$4,$A27:$B27,AQ$5:AQ$10,"#") -> #NAME? | AS27: =AO27-AQ27 -> #NAME? | AU27: =W27+AC27+AI27+AO27 -> #NAME? | AW27: =Y27+AE27+AK27+AQ27 -> #NAME? | AY27: =AU27-AW27 -> #NAME? | BA27: =+Q27-AO27 -> #NAME? | BC27: =+S27-AQ27 -> #NAME? | BE27: =BA27-BC27 -> #NAME? | BG27: =_xll.GetCtData("CO-AMOUNT","CONS-AMOUNT",$A$1:$A$4,$A27:$B27,BG$5:BG$10,"#") -> #NAME? | BI27: =_xll.GetCtData("CO-AMOUNT","CONS-AMOUNT",$A$1:$A$4,$A27:$B27,BI$5:BI$10,"#") -> #NAME? | BK27: =BG27-BI27 -> #NAME? | BN27: =_xll.GetCtData("CO-AMOUNT","CONS-AMOUNT",$A$1:$A$4,$A27:$B27,BN$5:BN$10,"#") -> #NAME? | BP27: =_xll.GetCtData("CO-AMOUNT","CONS-AMOUNT",$A$1:$A$4,$A27:$B27,BP$5:BP$10,"#") -> #NAME? | BR27: =BN27-BP27 -> #NAME?
A28: OA sum AR028 | B28: {RU=G-DE}+{RU=G-DEPROMO} | C28: DE | D28: =CHOOSE([6]Traduction!$A$2,[6]Traduction!$A49,[6]Traduction!$B49) -> o/w Germany | E28: =_xll.GetCtData("CO-AMOUNT","CONS-AMOUNT",$A$1:$A$4,$A28:$B28,E$5:E$10,"#-93,515") -> #NAME? | G28: =_xll.GetCtData("CO-AMOUNT","CONS-AMOUNT",$A$1:$A$4,$A28:$B28,G$5:G$10,"#-85,636") -> #NAME? | I28: =E28-G28 -> #NAME? | K28: =_xll.GetCtData("CO-AMOUNT","CONS-AMOUNT",$A$1:$A$4,$A28:$B28,K$5:K$10,"#-148,525") -> #NAME? | M28: =_xll.GetCtData("CO-AMOUNT","CONS-AMOUNT",$A$1:$A$4,$A28:$B28,M$5:M$10,"#-154,48") -> #NAME? | O28: =K28-M28 -> #NAME? | Q28: =_xll.GetCtData("CO-AMOUNT","CONS-AMOUNT",$A$1:$A$4,$A28:$B28,Q$5:Q$10,"#-242,04") -> #NAME? | S28: =_xll.GetCtData("CO-AMOUNT","CONS-AMOUNT",$A$1:$A$4,$A28:$B28,S$5:S$10,"#-240,116") -> #NAME? | U28: =Q28-S28 -> #NAME? | W28: =_xll.GetCtData("CO-AMOUNT","CONS-AMOUNT",$A$1:$A$4,$A28:$B28,W$5:W$10,"#") -> #NAME? | Y28: =_xll.GetCtData("CO-AMOUNT","CONS-AMOUNT",$A$1:$A$4,$A28:$B28,Y$5:Y$10,"#") -> #NAME? | AA28: =W28-Y28 -> #NAME? | AC28: =_xll.GetCtData("CO-AMOUNT","CONS-AMOUNT",$A$1:$A$4,$A28:$B28,AC$5:AC$10,"#-26,862") -> #NAME? | AE28: =_xll.GetCtData("CO-AMOUNT","CONS-AMOUNT",$A$1:$A$4,$A28:$B28,AE$5:AE$10,"#-26,003") -> #NAME? | AG28: =AC28-AE28 -> #NAME? | AI28: =_xll.GetCtData("CO-AMOUNT","CONS-AMOUNT",$A$1:$A$4,$A28:$B28,AI$5:AI$10,"#") -> #NAME? | AK28: =_xll.GetCtData("CO-AMOUNT","CONS-AMOUNT",$A$1:$A$4,$A28:$B28,AK$5:AK$10,"#") -> #NAME? | AM28: =AI28-AK28 -> #NAME? | AO28: =_xll.GetCtData("CO-AMOUNT","CONS-AMOUNT",$A$1:$A$4,$A28:$B28,AO$5:AO$10,"#-0,244") -> #NAME? | AQ28: =_xll.GetCtData("CO-AMOUNT","CONS-AMOUNT",$A$1:$A$4,$A28:$B28,AQ$5:AQ$10,"#-0,18") -> #NAME? | AS28: =AO28-AQ28 -> #NAME? | AU28: =W28+AC28+AI28+AO28 -> #NAME? | AW28: =Y28+AE28+AK28+AQ28 -> #NAME? | AY28: =AU28-AW28 -> #NAME? | BA28: =+Q28-AO28 -> #NAME? | BC28: =+S28-AQ28 -> #NAME? | BE28: =BA28-BC28 -> #NAME? | BG28: =_xll.GetCtData("CO-AMOUNT","CONS-AMOUNT",$A$1:$A$4,$A28:$B28,BG$5:BG$10,"#-0,244") -> #NAME? | BI28: =_xll.GetCtData("CO-AMOUNT","CONS-AMOUNT",$A$1:$A$4,$A28:$B28,BI$5:BI$10,"#-0,18") -> #NAME? | BK28: =BG28-BI28 -> #NAME? | BN28: =_xll.GetCtData("CO-AMOUNT","CONS-AMOUNT",$A$1:$A$4,$A28:$B28,BN$5:BN$10,"#") -> #NAME? | BP28: =_xll.GetCtData("CO-AMOUNT","CONS-AMOUNT",$A$1:$A$4,$A28:$B28,BP$5:BP$10,"#") -> #NAME? | BR28: =BN28-BP28 -> #NAME?
A29: OA sum AR028 | B29: {RU=G-PRTPROMO} | C29: PRT | D29: =CHOOSE([6]Traduction!$A$2,[6]Traduction!$A50,[6]Traduction!$B50) -> o/w Portugal | E29: =_xll.GetCtData("CO-AMOUNT","CONS-AMOUNT",$A$1:$A$4,$A29:$B29,E$5:E$10,"#321") -> #NAME? | G29: =_xll.GetCtData("CO-AMOUNT","CONS-AMOUNT",$A$1:$A$4,$A29:$B29,G$5:G$10,"#200,183") -> #NAME? | I29: =E29-G29 -> #NAME? | K29: =_xll.GetCtData("CO-AMOUNT","CONS-AMOUNT",$A$1:$A$4,$A29:$B29,K$5:K$10,"#-182,3") -> #NAME? | M29: =_xll.GetCtData("CO-AMOUNT","CONS-AMOUNT",$A$1:$A$4,$A29:$B29,M$5:M$10,"#-231,556") -> #NAME? | O29: =K29-M29 -> #NAME? | Q29: =_xll.GetCtData("CO-AMOUNT","CONS-AMOUNT",$A$1:$A$4,$A29:$B29,Q$5:Q$10,"#138,7") -> #NAME? | S29: =_xll.GetCtData("CO-AMOUNT","CONS-AMOUNT",$A$1:$A$4,$A29:$B29,S$5:S$10,"#-31,373") -> #NAME? | U29: =Q29-S29 -> #NAME? | W29: =_xll.GetCtData("CO-AMOUNT","CONS-AMOUNT",$A$1:$A$4,$A29:$B29,W$5:W$10,"#") -> #NAME? | Y29: =_xll.GetCtData("CO-AMOUNT","CONS-AMOUNT",$A$1:$A$4,$A29:$B29,Y$5:Y$10,"#") -> #NAME? | AA29: =W29-Y29 -> #NAME? | AC29: =_xll.GetCtData("CO-AMOUNT","CONS-AMOUNT",$A$1:$A$4,$A29:$B29,AC$5:AC$10,"#-24,25") -> #NAME? | AE29: =_xll.GetCtData("CO-AMOUNT","CONS-AMOUNT",$A$1:$A$4,$A29:$B29,AE$5:AE$10,"#-24,333") -> #NAME? | AG29: =AC29-AE29 -> #NAME? | AI29: =_xll.GetCtData("CO-AMOUNT","CONS-AMOUNT",$A$1:$A$4,$A29:$B29,AI$5:AI$10,"#") -> #NAME? | AK29: =_xll.GetCtData("CO-AMOUNT","CONS-AMOUNT",$A$1:$A$4,$A29:$B29,AK$5:AK$10,"#") -> #NAME? | AM29: =AI29-AK29 -> #NAME? | AO29: =_xll.GetCtData("CO-AMOUNT","CONS-AMOUNT",$A$1:$A$4,$A29:$B29,AO$5:AO$10,"#-8,1") -> #NAME? | AQ29: =_xll.GetCtData("CO-AMOUNT","CONS-AMOUNT",$A$1:$A$4,$A29:$B29,AQ$5:AQ$10,"#-8,692") -> #NAME? | AS29: =AO29-AQ29 -> #NAME? | AU29: =W29+AC29+AI29+AO29 -> #NAME? | AW29: =Y29+AE29+AK29+AQ29 -> #NAME? | AY29: =AU29-AW29 -> #NAME? | BA29: =+Q29-AO29 -> #NAME? | BC29: =+S29-AQ29 -> #NAME? | BE29: =BA29-BC29 -> #NAME? | BG29: =_xll.GetCtData("CO-AMOUNT","CONS-AMOUNT",$A$1:$A$4,$A29:$B29,BG$5:BG$10,"#") -> #NAME? | BI29: =_xll.GetCtData("CO-AMOUNT","CONS-AMOUNT",$A$1:$A$4,$A29:$B29,BI$5:BI$10,"#-8,692") -> #NAME? | BK29: =BG29-BI29 -> #NAME? | BN29: =_xll.GetCtData("CO-AMOUNT","CONS-AMOUNT",$A$1:$A$4,$A29:$B29,BN$5:BN$10,"#-8,1") -> #NAME? | BP29: =_xll.GetCtData("CO-AMOUNT","CONS-AMOUNT",$A$1:$A$4,$A29:$B29,BP$5:BP$10,"#") -> #NAME? | BR29: =BN29-BP29 -> #NAME?
A30: {OA=OA040}+{OA=OA041} | B30: RU=G-UKPROMO | C30: UK | D30: =CHOOSE([6]Traduction!$A$2,[6]Traduction!$A52,[6]Traduction!$B52) -> o/w UK | E30: =_xll.GetCtData("CO-AMOUNT","CONS-AMOUNT",$A$1:$A$4,$A30:$B30,E$5:E$10,"#12,6338514234335") -> #NAME? | G30: =_xll.GetCtData("CO-AMOUNT","CONS-AMOUNT",$A$1:$A$4,$A30:$B30,G$5:G$10,"#12,5719900262874") -> #NAME? | I30: =E30-G30 -> #NAME? | K30: =_xll.GetCtData("CO-AMOUNT","CONS-AMOUNT",$A$1:$A$4,$A30:$B30,K$5:K$10,"#-80,2485658327114") -> #NAME? | M30: =_xll.GetCtData("CO-AMOUNT","CONS-AMOUNT",$A$1:$A$4,$A30:$B30,M$5:M$10,"#-67,7849407197164") -> #NAME? | O30: =K30-M30 -> #NAME? | Q30: =_xll.GetCtData("CO-AMOUNT","CONS-AMOUNT",$A$1:$A$4,$A30:$B30,Q$5:Q$10,"#-67,6147144092779") -> #NAME? | S30: =_xll.GetCtData("CO-AMOUNT","CONS-AMOUNT",$A$1:$A$4,$A30:$B30,S$5:S$10,"#-55,212950693429") -> #NAME? | U30: =Q30-S30 -> #NAME? | W30: =_xll.GetCtData("CO-AMOUNT","CONS-AMOUNT",$A$1:$A$4,$A30:$B30,W$5:W$10,"#") -> #NAME? | Y30: =_xll.GetCtData("CO-AMOUNT","CONS-AMOUNT",$A$1:$A$4,$A30:$B30,Y$5:Y$10,"#") -> #NAME? | AA30: =W30-Y30 -> #NAME? | AC30: =_xll.GetCtData("CO-AMOUNT","CONS-AMOUNT",$A$1:$A$4,$A30:$B30,AC$5:AC$10,"#") -> #NAME? | AE30: =_xll.GetCtData("CO-AMOUNT","CONS-AMOUNT",$A$1:$A$4,$A30:$B30,AE$5:AE$10,"#") -> #NAME? | AG30: =AC30-AE30 -> #NAME? | AI30: =_xll.GetCtData("CO-AMOUNT","CONS-AMOUNT",$A$1:$A$4,$A30:$B30,AI$5:AI$10,"#") -> #NAME? | AK30: =_xll.GetCtData("CO-AMOUNT","CONS-AMOUNT",$A$1:$A$4,$A30:$B30,AK$5:AK$10,"#") -> #NAME? | AM30: =AI30-AK30 -> #NAME? | AO30: =_xll.GetCtData("CO-AMOUNT","CONS-AMOUNT",$A$1:$A$4,$A30:$B30,AO$5:AO$10,"#-1,47414127821284") -> #NAME? | AQ30: =_xll.GetCtData("CO-AMOUNT","CONS-AMOUNT",$A$1:$A$4,$A30:$B30,AQ$5:AQ$10,"#-1,4878777187074") -> #NAME? | AS30: =AO30-AQ30 -> #NAME? | AU30: =W30+AC30+AI30+AO30 -> #NAME? | AW30: =Y30+AE30+AK30+AQ30 -> #NAME? | AY30: =AU30-AW30 -> #NAME? | BA30: =+Q30-AO30 -> #NAME? | BC30: =+S30-AQ30 -> #NAME? | BE30: =BA30-BC30 -> #NAME? | BG30: =_xll.GetCtData("CO-AMOUNT","CONS-AMOUNT",$A$1:$A$4,$A30:$B30,BG$5:BG$10,"#-1,47414127821284") -> #NAME? | BI30: =_xll.GetCtData("CO-AMOUNT","CONS-AMOUNT",$A$1:$A$4,$A30:$B30,BI$5:BI$10,"#-1,4878777187074") -> #NAME? | BK30: =BG30-BI30 -> #NAME? | BN30: =_xll.GetCtData("CO-AMOUNT","CONS-AMOUNT",$A$1:$A$4,$A30:$B30,BN$5:BN$10,"#") -> #NAME? | BP30: =_xll.GetCtData("CO-AMOUNT","CONS-AMOUNT",$A$1:$A$4,$A30:$B30,BP$5:BP$10,"#") -> #NAME? | BR30: =BN30-BP30 -> #NAME?
A31: {OA=OA040}+{OA=OA041} | B31: RU=G-UKPROMO | C31: UK GBP | D31: UK (GBP) | E31: =_xll.GetCtData("CO-AMOUNT","AMOUNT",$A$1:$A$4,$A31:$B31,E$5:E$10,"#10,97") -> #NAME? | G31: =_xll.GetCtData("CO-AMOUNT","AMOUNT",$A$1:$A$4,$A31:$B31,G$5:G$10,"#10,9") -> #NAME? | I31: =E31-G31 -> #NAME? | K31: =_xll.GetCtData("CO-AMOUNT","AMOUNT",$A$1:$A$4,$A31:$B31,K$5:K$10,"#-69,68") -> #NAME? | M31: =_xll.GetCtData("CO-AMOUNT","AMOUNT",$A$1:$A$4,$A31:$B31,M$5:M$10,"#-58,77") -> #NAME? | O31: =K31-M31 -> #NAME? | Q31: =_xll.GetCtData("CO-AMOUNT","AMOUNT",$A$1:$A$4,$A31:$B31,Q$5:Q$10,"#-58,71") -> #NAME? | S31: =_xll.GetCtData("CO-AMOUNT","AMOUNT",$A$1:$A$4,$A31:$B31,S$5:S$10,"#-47,87") -> #NAME? | U31: =Q31-S31 -> #NAME? | W31: =_xll.GetCtData("CO-AMOUNT","AMOUNT",$A$1:$A$4,$A31:$B31,W$5:W$10,"#") -> #NAME? | Y31: =_xll.GetCtData("CO-AMOUNT","AMOUNT",$A$1:$A$4,$A31:$B31,Y$5:Y$10,"#") -> #NAME? | AA31: =W31-Y31 -> #NAME? | AC31: =_xll.GetCtData("CO-AMOUNT","AMOUNT",$A$1:$A$4,$A31:$B31,AC$5:AC$10,"#") -> #NAME? | AE31: =_xll.GetCtData("CO-AMOUNT","AMOUNT",$A$1:$A$4,$A31:$B31,AE$5:AE$10,"#") -> #NAME? | AG31: =AC31-AE31 -> #NAME? | AI31: =_xll.GetCtData("CO-AMOUNT","AMOUNT",$A$1:$A$4,$A31:$B31,AI$5:AI$10,"#") -> #NAME? | AK31: =_xll.GetCtData("CO-AMOUNT","AMOUNT",$A$1:$A$4,$A31:$B31,AK$5:AK$10,"#") -> #NAME? | AM31: =AI31-AK31 -> #NAME? | AO31: =_xll.GetCtData("CO-AMOUNT","AMOUNT",$A$1:$A$4,$A31:$B31,AO$5:AO$10,"#-1,28") -> #NAME? | AQ31: =_xll.GetCtData("CO-AMOUNT","AMOUNT",$A$1:$A$4,$A31:$B31,AQ$5:AQ$10,"#-1,29") -> #NAME? | AS31: =AO31-AQ31 -> #NAME? | AU31: =W31+AC31+AI31+AO31 -> #NAME? | AW31: =Y31+AE31+AK31+AQ31 -> #NAME? | AY31: =AU31-AW31 -> #NAME? | BA31: =+Q31-AO31 -> #NAME? | BC31: =+S31-AQ31 -> #NAME? | BE31: =BA31-BC31 -> #NAME? | BG31: =_xll.GetCtData("CO-AMOUNT","AMOUNT",$A$1:$A$4,$A31:$B31,BG$5:BG$10,"#-1,28") -> #NAME? | BI31: =_xll.GetCtData("CO-AMOUNT","AMOUNT",$A$1:$A$4,$A31:$B31,BI$5:BI$10,"#-1,29") -> #NAME? | BK31: =BG31-BI31 -> #NAME? | BN31: =_xll.GetCtData("CO-AMOUNT","AMOUNT",$A$1:$A$4,$A31:$B31,BN$5:BN$10,"#") -> #NAME? | BP31: =_xll.GetCtData("CO-AMOUNT","AMOUNT",$A$1:$A$4,$A31:$B31,BP$5:BP$10,"#") -> #NAME? | BR31: =BN31-BP31 -> #NAME?
A32: OA sum AR028 | B32: RU=G-LX | C32: LUX | D32: =CHOOSE([6]Traduction!$A$2,[6]Traduction!$A53,[6]Traduction!$B53) -> o/w Luxembourg | E32: =_xll.GetCtData("CO-AMOUNT","CONS-AMOUNT",$A$1:$A$4,$A32:$B32,E$5:E$10,"#") -> #NAME? | G32: =_xll.GetCtData("CO-AMOUNT","CONS-AMOUNT",$A$1:$A$4,$A32:$B32,G$5:G$10,"#") -> #NAME? | I32: =E32-G32 -> #NAME? | K32: =_xll.GetCtData("CO-AMOUNT","CONS-AMOUNT",$A$1:$A$4,$A32:$B32,K$5:K$10,"#") -> #NAME? | M32: =_xll.GetCtData("CO-AMOUNT","CONS-AMOUNT",$A$1:$A$4,$A32:$B32,M$5:M$10,"#") -> #NAME? | O32: =K32-M32 -> #NAME? | Q32: =_xll.GetCtData("CO-AMOUNT","CONS-AMOUNT",$A$1:$A$4,$A32:$B32,Q$5:Q$10,"#") -> #NAME? | S32: =_xll.GetCtData("CO-AMOUNT","CONS-AMOUNT",$A$1:$A$4,$A32:$B32,S$5:S$10,"#") -> #NAME? | U32: =Q32-S32 -> #NAME? | W32: =_xll.GetCtData("CO-AMOUNT","CONS-AMOUNT",$A$1:$A$4,$A32:$B32,W$5:W$10,"#") -> #NAME? | Y32: =_xll.GetCtData("CO-AMOUNT","CONS-AMOUNT",$A$1:$A$4,$A32:$B32,Y$5:Y$10,"#") -> #NAME? | AA32: =W32-Y32 -> #NAME? | AC32: =_xll.GetCtData("CO-AMOUNT","CONS-AMOUNT",$A$1:$A$4,$A32:$B32,AC$5:AC$10,"#") -> #NAME? | AE32: =_xll.GetCtData("CO-AMOUNT","CONS-AMOUNT",$A$1:$A$4,$A32:$B32,AE$5:AE$10,"#") -> #NAME? | AG32: =AC32-AE32 -> #NAME? | AI32: =_xll.GetCtData("CO-AMOUNT","CONS-AMOUNT",$A$1:$A$4,$A32:$B32,AI$5:AI$10,"#") -> #NAME? | AK32: =_xll.GetCtData("CO-AMOUNT","CONS-AMOUNT",$A$1:$A$4,$A32:$B32,AK$5:AK$10,"#") -> #NAME? | AM32: =AI32-AK32 -> #NAME? | AO32: =_xll.GetCtData("CO-AMOUNT","CONS-AMOUNT",$A$1:$A$4,$A32:$B32,AO$5:AO$10,"#") -> #NAME? | AQ32: =_xll.GetCtData("CO-AMOUNT","CONS-AMOUNT",$A$1:$A$4,$A32:$B32,AQ$5:AQ$10,"#") -> #NAME? | AS32: =AO32-AQ32 -> #NAME? | AU32: =W32+AC32+AI32+AO32 -> #NAME? | AW32: =Y32+AE32+AK32+AQ32 -> #NAME? | AY32: =AU32-AW32 -> #NAME? | BA32: =+Q32-AO32 -> #NAME? | BC32: =+S32-AQ32 -> #NAME? | BE32: =BA32-BC32 -> #NAME? | BG32: =_xll.GetCtData("CO-AMOUNT","CONS-AMOUNT",$A$1:$A$4,$A32:$B32,BG$5:BG$10,"#") -> #NAME? | BI32: =_xll.GetCtData("CO-AMOUNT","CONS-AMOUNT",$A$1:$A$4,$A32:$B32,BI$5:BI$10,"#") -> #NAME? | BK32: =BG32-BI32 -> #NAME? | BN32: =_xll.GetCtData("CO-AMOUNT","CONS-AMOUNT",$A$1:$A$4,$A32:$B32,BN$5:BN$10,"#") -> #NAME? | BP32: =_xll.GetCtData("CO-AMOUNT","CONS-AMOUNT",$A$1:$A$4,$A32:$B32,BP$5:BP$10,"#") -> #NAME? | BR32: =BN32-BP32 -> #NAME?
A33: OA=OA045 | B33: {RU=G-FRMP} | C33: FR | D33: =CHOOSE([6]Traduction!$A$2,[6]Traduction!$A54,[6]Traduction!$B54) -> o/w International Teams | E33: =_xll.GetCtData("CO-AMOUNT","CONS-AMOUNT",$A$1:$A$4,$A33:$B33,E$5:E$10,"#96,35") -> #NAME? | G33: =_xll.GetCtData("CO-AMOUNT","CONS-AMOUNT",$A$1:$A$4,$A33:$B33,G$5:G$10,"#426,4") -> #NAME? | I33: =E33-G33 -> #NAME? | K33: =_xll.GetCtData("CO-AMOUNT","CONS-AMOUNT",$A$1:$A$4,$A33:$B33,K$5:K$10,"#-108,71") -> #NAME? | M33: =_xll.GetCtData("CO-AMOUNT","CONS-AMOUNT",$A$1:$A$4,$A33:$B33,M$5:M$10,"#-111,61") -> #NAME? | O33: =K33-M33 -> #NAME? | Q33: =_xll.GetCtData("CO-AMOUNT","CONS-AMOUNT",$A$1:$A$4,$A33:$B33,Q$5:Q$10,"#-12,36") -> #NAME? | S33: =_xll.GetCtData("CO-AMOUNT","CONS-AMOUNT",$A$1:$A$4,$A33:$B33,S$5:S$10,"#314,79") -> #NAME? | U33: =Q33-S33 -> #NAME? | W33: =_xll.GetCtData("CO-AMOUNT","CONS-AMOUNT",$A$1:$A$4,$A33:$B33,W$5:W$10,"#") -> #NAME? | Y33: =_xll.GetCtData("CO-AMOUNT","CONS-AMOUNT",$A$1:$A$4,$A33:$B33,Y$5:Y$10,"#") -> #NAME? | AA33: =W33-Y33 -> #NAME? | AC33: =_xll.GetCtData("CO-AMOUNT","CONS-AMOUNT",$A$1:$A$4,$A33:$B33,AC$5:AC$10,"#70,78") -> #NAME? | AE33: =_xll.GetCtData("CO-AMOUNT","CONS-AMOUNT",$A$1:$A$4,$A33:$B33,AE$5:AE$10,"#67,77") -> #NAME? | AG33: =AC33-AE33 -> #NAME? | AI33: =_xll.GetCtData("CO-AMOUNT","CONS-AMOUNT",$A$1:$A$4,$A33:$B33,AI$5:AI$10,"#") -> #NAME? | AK33: =_xll.GetCtData("CO-AMOUNT","CONS-AMOUNT",$A$1:$A$4,$A33:$B33,AK$5:AK$10,"#") -> #NAME? | AM33: =AI33-AK33 -> #NAME? | AO33: =_xll.GetCtData("CO-AMOUNT","CONS-AMOUNT",$A$1:$A$4,$A33:$B33,AO$5:AO$10,"#") -> #NAME? | AQ33: =_xll.GetCtData("CO-AMOUNT","CONS-AMOUNT",$A$1:$A$4,$A33:$B33,AQ$5:AQ$10,"#") -> #NAME? | AS33: =AO33-AQ33 -> #NAME? | AU33: =W33+AC33+AI33+AO33 -> #NAME? | AW33: =Y33+AE33+AK33+AQ33 -> #NAME? | AY33: =AU33-AW33 -> #NAME? | BA33: =+Q33-AO33 -> #NAME? | BC33: =+S33-AQ33 -> #NAME? | BE33: =BA33-BC33 -> #NAME? | BG33: =_xll.GetCtData("CO-AMOUNT","CONS-AMOUNT",$A$1:$A$4,$A33:$B33,BG$5:BG$10,"#") -> #NAME? | BI33: =_xll.GetCtData("CO-AMOUNT","CONS-AMOUNT",$A$1:$A$4,$A33:$B33,BI$5:BI$10,"#") -> #NAME? | BK33: =BG33-BI33 -> #NAME? | BN33: =_xll.GetCtData("CO-AMOUNT","CONS-AMOUNT",$A$1:$A$4,$A33:$B33,BN$5:BN$10,"#") -> #NAME? | BP33: =_xll.GetCtData("CO-AMOUNT","CONS-AMOUNT",$A$1:$A$4,$A33:$B33,BP$5:BP$10,"#") -> #NAME? | BR33: =BN33-BP33 -> #NAME?
D34: Investment Management | E34: =SUM(E35:E46)-E44-E39-E40 -> #NAME? | G34: =SUM(G35:G46)-G44-G39-G40 -> #NAME? | I34: =E34-G34 -> #NAME? | K34: =SUM(K35:K46)-K44-K39-K40 -> #NAME? | M34: =SUM(M35:M46)-M44-M39-M40 -> #NAME? | O34: =K34-M34 -> #NAME? | Q34: =SUM(Q35:Q46)-Q44-Q39-Q40 -> #NAME? | S34: =SUM(S35:S46)-S44-S39-S40 -> #NAME? | U34: =Q34-S34 -> #NAME? | W34: =SUM(W35:W46)-W44 -> #NAME? | Y34: =SUM(Y35:Y46)-Y44 -> #NAME? | AA34: =W34-Y34 -> #NAME? | AC34: =SUM(AC35:AC46)-AC44 -> #NAME? | AE34: =SUM(AE35:AE46)-AE44 -> #NAME? | AG34: =AC34-AE34 -> #NAME? | AI34: =SUM(AI35:AI46)-AI44 -> #NAME? | AK34: =SUM(AK35:AK46)-AK44 -> #NAME? | AM34: =AI34-AK34 -> #NAME? | AO34: =SUM(AO35:AO46)-AO44 -> #NAME? | AQ34: =SUM(AQ35:AQ46)-AQ44 -> #NAME? | AS34: =AO34-AQ34 -> #NAME? | AU34: =W34+AC34+AI34+AO34 -> #NAME? | AW34: =Y34+AE34+AK34+AQ34 -> #NAME? | AY34: =AU34-AW34 -> #NAME? | BA34: =+Q34-AO34 -> #NAME? | BC34: =+S34-AQ34 -> #NAME? | BE34: =BA34-BC34 -> #NAME? | BG34: =SUM(BG35:BG46)-BG44 -> #NAME? | BI34: =SUM(BI35:BI46)-BI44 -> #NAME? | BK34: =BG34-BI34 -> #NAME? | BN34: =SUM(BN35:BN46)-BN44 -> #NAME? | BP34: =SUM(BP35:BP46)-BP44 -> #NAME? | BR34: =BN34-BP34 -> #NAME?
A35: {OA=OA060}+{OA=OA061}+{OA=OA069}+{OA=OA060E}+{OA=OA060O}+{OA=OA061O} | B35: {RU=G-CENTRAL}+{RU=P-CENTRAL} | C35: CENTRAL | D35: G-central | E35: =_xll.GetCtData("CO-AMOUNT","CONS-AMOUNT",$A$1:$A$4,$A35:$B35,E$5:E$10,"#") -> #NAME? | G35: =_xll.GetCtData("CO-AMOUNT","CONS-AMOUNT",$A$1:$A$4,$A35:$B35,G$5:G$10,"#") -> #NAME? | I35: =E35-G35 -> #NAME? | K35: =_xll.GetCtData("CO-AMOUNT","CONS-AMOUNT",$A$1:$A$4,$A35:$B35,K$5:K$10,"#") -> #NAME? | M35: =_xll.GetCtData("CO-AMOUNT","CONS-AMOUNT",$A$1:$A$4,$A35:$B35,M$5:M$10,"#") -> #NAME? | O35: =K35-M35 -> #NAME? | Q35: =_xll.GetCtData("CO-AMOUNT","CONS-AMOUNT",$A$1:$A$4,$A35:$B35,Q$5:Q$10,"#") -> #NAME? | S35: =_xll.GetCtData("CO-AMOUNT","CONS-AMOUNT",$A$1:$A$4,$A35:$B35,S$5:S$10,"#") -> #NAME? | U35: =Q35-S35 -> #NAME? | W35: =_xll.GetCtData("CO-AMOUNT","CONS-AMOUNT",$A$1:$A$4,$A35:$B35,W$5:W$10,"#") -> #NAME? | Y35: =_xll.GetCtData("CO-AMOUNT","CONS-AMOUNT",$A$1:$A$4,$A35:$B35,Y$5:Y$10,"#") -> #NAME? | AA35: =W35-Y35 -> #NAME? | AC35: =_xll.GetCtData("CO-AMOUNT","CONS-AMOUNT",$A$1:$A$4,$A35:$B35,AC$5:AC$10,"#") -> #NAME? | AE35: =_xll.GetCtData("CO-AMOUNT","CONS-AMOUNT",$A$1:$A$4,$A35:$B35,AE$5:AE$10,"#") -> #NAME? | AG35: =AC35-AE35 -> #NAME? | AI35: =_xll.GetCtData("CO-AMOUNT","CONS-AMOUNT",$A$1:$A$4,$A35:$B35,AI$5:AI$10,"#") -> #NAME? | AK35: =_xll.GetCtData("CO-AMOUNT","CONS-AMOUNT",$A$1:$A$4,$A35:$B35,AK$5:AK$10,"#") -> #NAME? | AM35: =AI35-AK35 -> #NAME? | AO35: =_xll.GetCtData("CO-AMOUNT","CONS-AMOUNT",$A$1:$A$4,$A35:$B35,AO$5:AO$10,"#") -> #NAME? | AQ35: =_xll.GetCtData("CO-AMOUNT","CONS-AMOUNT",$A$1:$A$4,$A35:$B35,AQ$5:AQ$10,"#") -> #NAME? | AS35: =AO35-AQ35 -> #NAME? | AU35: =W35+AC35+AI35+AO35 -> #NAME? | AW35: =Y35+AE35+AK35+AQ35 -> #NAME? | AY35: =AU35-AW35 -> #NAME? | BA35: =+Q35-AO35 -> #NAME? | BC35: =+S35-AQ35 -> #NAME? | BE35: =BA35-BC35 -> #NAME? | BG35: =_xll.GetCtData("CO-AMOUNT","CONS-AMOUNT",$A$1:$A$4,$A35:$B35,BG$5:BG$10,"#") -> #NAME? | BI35: =_xll.GetCtData("CO-AMOUNT","CONS-AMOUNT",$A$1:$A$4,$A35:$B35,BI$5:BI$10,"#") -> #NAME? | BK35: =BG35-BI35 -> #NAME? | BN35: =_xll.GetCtData("CO-AMOUNT","CONS-AMOUNT",$A$1:$A$4,$A35:$B35,BN$5:BN$10,"#") -> #NAME? | BP35: =_xll.GetCtData("CO-AMOUNT","CONS-AMOUNT",$A$1:$A$4,$A35:$B35,BP$5:BP$10,"#") -> #NAME? | BR35: =BN35-BP35 -> #NAME?
A36: {OA=OA069}+{OA=OA005} | B36: {RU=G-FRMP}+{RU=P-FRMP}+{RU=G-REIMDE}+{RU=G-REIMI} | C36: DE | D36: =CHOOSE([6]Traduction!$A$2,[6]Traduction!$A62,[6]Traduction!$B62) -> o/w Coordination Team | E36: =_xll.GetCtData("CO-AMOUNT","CONS-AMOUNT",$A$1:$A$4,$A36:$B36,E$5:E$10,"#1,00000000054479E-03") -> #NAME? | G36: =_xll.GetCtData("CO-AMOUNT","CONS-AMOUNT",$A$1:$A$4,$A36:$B36,G$5:G$10,"#-27,053") -> #NAME? | I36: =E36-G36 -> #NAME? | K36: =_xll.GetCtData("CO-AMOUNT","CONS-AMOUNT",$A$1:$A$4,$A36:$B36,K$5:K$10,"#-1,182") -> #NAME? | M36: =_xll.GetCtData("CO-AMOUNT","CONS-AMOUNT",$A$1:$A$4,$A36:$B36,M$5:M$10,"#-0,398") -> #NAME? | O36: =K36-M36 -> #NAME? | Q36: =_xll.GetCtData("CO-AMOUNT","CONS-AMOUNT",$A$1:$A$4,$A36:$B36,Q$5:Q$10,"#-1,18100000000015") -> #NAME? | S36: =_xll.GetCtData("CO-AMOUNT","CONS-AMOUNT",$A$1:$A$4,$A36:$B36,S$5:S$10,"#-27,451") -> #NAME? | U36: =Q36-S36 -> #NAME? | W36: =_xll.GetCtData("CO-AMOUNT","CONS-AMOUNT",$A$1:$A$4,$A36:$B36,W$5:W$10,"#") -> #NAME? | Y36: =_xll.GetCtData("CO-AMOUNT","CONS-AMOUNT",$A$1:$A$4,$A36:$B36,Y$5:Y$10,"#") -> #NAME? | AA36: =W36-Y36 -> #NAME? | AC36: =_xll.GetCtData("CO-AMOUNT","CONS-AMOUNT",$A$1:$A$4,$A36:$B36,AC$5:AC$10,"#") -> #NAME? | AE36: =_xll.GetCtData("CO-AMOUNT","CONS-AMOUNT",$A$1:$A$4,$A36:$B36,AE$5:AE$10,"#") -> #NAME? | AG36: =AC36-AE36 -> #NAME? | AI36: =_xll.GetCtData("CO-AMOUNT","CONS-AMOUNT",$A$1:$A$4,$A36:$B36,AI$5:AI$10,"#") -> #NAME? | AK36: =_xll.GetCtData("CO-AMOUNT","CONS-AMOUNT",$A$1:$A$4,$A36:$B36,AK$5:AK$10,"#") -> #NAME? | AM36: =AI36-AK36 -> #NAME? | AO36: =_xll.GetCtData("CO-AMOUNT","CONS-AMOUNT",$A$1:$A$4,$A36:$B36,AO$5:AO$10,"#") -> #NAME? | AQ36: =_xll.GetCtData("CO-AMOUNT","CONS-AMOUNT",$A$1:$A$4,$A36:$B36,AQ$5:AQ$10,"#") -> #NAME? | AS36: =AO36-AQ36 -> #NAME? | AU36: =W36+AC36+AI36+AO36 -> #NAME? | AW36: =Y36+AE36+AK36+AQ36 -> #NAME? | AY36: =AU36-AW36 -> #NAME? | BA36: =+Q36-AO36 -> #NAME? | BC36: =+S36-AQ36 -> #NAME? | BE36: =BA36-BC36 -> #NAME? | BG36: =_xll.GetCtData("CO-AMOUNT","CONS-AMOUNT",$A$1:$A$4,$A36:$B36,BG$5:BG$10,"#") -> #NAME? | BI36: =_xll.GetCtData("CO-AMOUNT","CONS-AMOUNT",$A$1:$A$4,$A36:$B36,BI$5:BI$10,"#") -> #NAME? | BK36: =BG36-BI36 -> #NAME? | BN36: =_xll.GetCtData("CO-AMOUNT","CONS-AMOUNT",$A$1:$A$4,$A36:$B36,BN$5:BN$10,"#") -> #NAME? | BP36: =_xll.GetCtData("CO-AMOUNT","CONS-AMOUNT",$A$1:$A$4,$A36:$B36,BP$5:BP$10,"#") -> #NAME? | BR36: =BN36-BP36 -> #NAME?
A37: {OA=OA060}+{OA=OA060E}+{OA=OA060O}+{OA=OA061}+{OA=OA061O} | B37: {RU=G-FRMP}+{RU=P-FRMP} | C37: FR | D37: =CHOOSE([6]Traduction!$A$2,[6]Traduction!$A45,[6]Traduction!$B45) -> o/w France | E37: =_xll.GetCtData("CO-AMOUNT","CONS-AMOUNT",$A$1:$A$4,$A37:$B37,E$5:E$10,"#-1,99999999995271E-03") -> #NAME? | G37: =_xll.GetCtData("CO-AMOUNT","CONS-AMOUNT",$A$1:$A$4,$A37:$B37,G$5:G$10,"#") -> #NAME? | I37: =E37-G37 -> #NAME? | K37: =_xll.GetCtData("CO-AMOUNT","CONS-AMOUNT",$A$1:$A$4,$A37:$B37,K$5:K$10,"#") -> #NAME? | M37: =_xll.GetCtData("CO-AMOUNT","CONS-AMOUNT",$A$1:$A$4,$A37:$B37,M$5:M$10,"#") -> #NAME? | O37: =K37-M37 -> #NAME? | Q37: =_xll.GetCtData("CO-AMOUNT","CONS-AMOUNT",$A$1:$A$4,$A37:$B37,Q$5:Q$10,"#-1,99999999995271E-03") -> #NAME? | S37: =_xll.GetCtData("CO-AMOUNT","CONS-AMOUNT",$A$1:$A$4,$A37:$B37,S$5:S$10,"#") -> #NAME? | U37: =Q37-S37 -> #NAME? | W37: =_xll.GetCtData("CO-AMOUNT","CONS-AMOUNT",$A$1:$A$4,$A37:$B37,W$5:W$10,"#") -> #NAME? | Y37: =_xll.GetCtData("CO-AMOUNT","CONS-AMOUNT",$A$1:$A$4,$A37:$B37,Y$5:Y$10,"#") -> #NAME? | AA37: =W37-Y37 -> #NAME? | AC37: =_xll.GetCtData("CO-AMOUNT","CONS-AMOUNT",$A$1:$A$4,$A37:$B37,AC$5:AC$10,"#") -> #NAME? | AE37: =_xll.GetCtData("CO-AMOUNT","CONS-AMOUNT",$A$1:$A$4,$A37:$B37,AE$5:AE$10,"#") -> #NAME? | AG37: =AC37-AE37 -> #NAME? | AI37: =_xll.GetCtData("CO-AMOUNT","CONS-AMOUNT",$A$1:$A$4,$A37:$B37,AI$5:AI$10,"#") -> #NAME? | AK37: =_xll.GetCtData("CO-AMOUNT","CONS-AMOUNT",$A$1:$A$4,$A37:$B37,AK$5:AK$10,"#") -> #NAME? | AM37: =AI37-AK37 -> #NAME? | AO37: =_xll.GetCtData("CO-AMOUNT","CONS-AMOUNT",$A$1:$A$4,$A37:$B37,AO$5:AO$10,"#") -> #NAME? | AQ37: =_xll.GetCtData("CO-AMOUNT","CONS-AMOUNT",$A$1:$A$4,$A37:$B37,AQ$5:AQ$10,"#") -> #NAME? | AS37: =AO37-AQ37 -> #NAME? | AU37: =W37+AC37+AI37+AO37 -> #NAME? | AW37: =Y37+AE37+AK37+AQ37 -> #NAME? | AY37: =AU37-AW37 -> #NAME? | BA37: =+Q37-AO37 -> #NAME? | BC37: =+S37-AQ37 -> #NAME? | BE37: =BA37-BC37 -> #NAME? | BG37: =_xll.GetCtData("CO-AMOUNT","CONS-AMOUNT",$A$1:$A$4,$A37:$B37,BG$5:BG$10,"#") -> #NAME? | BI37: =_xll.GetCtData("CO-AMOUNT","CONS-AMOUNT",$A$1:$A$4,$A37:$B37,BI$5:BI$10,"#") -> #NAME? | BK37: =BG37-BI37 -> #NAME? | BN37: =_xll.GetCtData("CO-AMOUNT","CONS-AMOUNT",$A$1:$A$4,$A37:$B37,BN$5:BN$10,"#") -> #NAME? | BP37: =_xll.GetCtData("CO-AMOUNT","CONS-AMOUNT",$A$1:$A$4,$A37:$B37,BP$5:BP$10,"#") -> #NAME? | BR37: =BN37-BP37 -> #NAME?
A38: {OA=OA060}+{OA=OA061}+{OA=OA060E}+{OA=OA061O} | B38: {RU=G-DE}+{RU=P-DE}+{RU=G-REIMDE}+{RU=G-REIMI} | C38: DE | D38: =CHOOSE([6]Traduction!$A$2,[6]Traduction!$A49,[6]Traduction!$B49) -> o/w Germany | E38: =_xll.GetCtData("CO-AMOUNT","CONS-AMOUNT",$A$1:$A$4,$A38:$B38,E$5:E$10,"#0") -> #NAME? | G38: =_xll.GetCtData("CO-AMOUNT","CONS-AMOUNT",$A$1:$A$4,$A38:$B38,G$5:G$10,"#") -> #NAME? | I38: =E38-G38 -> #NAME? | K38: =_xll.GetCtData("CO-AMOUNT","CONS-AMOUNT",$A$1:$A$4,$A38:$B38,K$5:K$10,"#") -> #NAME? | M38: =_xll.GetCtData("CO-AMOUNT","CONS-AMOUNT",$A$1:$A$4,$A38:$B38,M$5:M$10,"#") -> #NAME? | O38: =K38-M38 -> #NAME? | Q38: =_xll.GetCtData("CO-AMOUNT","CONS-AMOUNT",$A$1:$A$4,$A38:$B38,Q$5:Q$10,"#0") -> #NAME? | S38: =_xll.GetCtData("CO-AMOUNT","CONS-AMOUNT",$A$1:$A$4,$A38:$B38,S$5:S$10,"#") -> #NAME? | U38: =Q38-S38 -> #NAME? | W38: =_xll.GetCtData("CO-AMOUNT","CONS-AMOUNT",$A$1:$A$4,$A38:$B38,W$5:W$10,"#") -> #NAME? | Y38: =_xll.GetCtData("CO-AMOUNT","CONS-AMOUNT",$A$1:$A$4,$A38:$B38,Y$5:Y$10,"#") -> #NAME? | AA38: =W38-Y38 -> #NAME? | AC38: =_xll.GetCtData("CO-AMOUNT","CONS-AMOUNT",$A$1:$A$4,$A38:$B38,AC$5:AC$10,"#") -> #NAME? | AE38: =_xll.GetCtData("CO-AMOUNT","CONS-AMOUNT",$A$1:$A$4,$A38:$B38,AE$5:AE$10,"#") -> #NAME? | AG38: =AC38-AE38 -> #NAME? | AI38: =_xll.GetCtData("CO-AMOUNT","CONS-AMOUNT",$A$1:$A$4,$A38:$B38,AI$5:AI$10,"#") -> #NAME? | AK38: =_xll.GetCtData("CO-AMOUNT","CONS-AMOUNT",$A$1:$A$4,$A38:$B38,AK$5:AK$10,"#") -> #NAME? | AM38: =AI38-AK38 -> #NAME? | AO38: =_xll.GetCtData("CO-AMOUNT","CONS-AMOUNT",$A$1:$A$4,$A38:$B38,AO$5:AO$10,"#") -> #NAME? | AQ38: =_xll.GetCtData("CO-AMOUNT","CONS-AMOUNT",$A$1:$A$4,$A38:$B38,AQ$5:AQ$10,"#") -> #NAME? | AS38: =AO38-AQ38 -> #NAME? | AU38: =W38+AC38+AI38+AO38 -> #NAME? | AW38: =Y38+AE38+AK38+AQ38 -> #NAME? | AY38: =AU38-AW38 -> #NAME? | BA38: =+Q38-AO38 -> #NAME? | BC38: =+S38-AQ38 -> #NAME? | BE38: =BA38-BC38 -> #NAME? | BG38: =_xll.GetCtData("CO-AMOUNT","CONS-AMOUNT",$A$1:$A$4,$A38:$B38,BG$5:BG$10,"#") -> #NAME? | BI38: =_xll.GetCtData("CO-AMOUNT","CONS-AMOUNT",$A$1:$A$4,$A38:$B38,BI$5:BI$10,"#") -> #NAME? | BK38: =BG38-BI38 -> #NAME? | BN38: =_xll.GetCtData("CO-AMOUNT","CONS-AMOUNT",$A$1:$A$4,$A38:$B38,BN$5:BN$10,"#") -> #NAME? | BP38: =_xll.GetCtData("CO-AMOUNT","CONS-AMOUNT",$A$1:$A$4,$A38:$B38,BP$5:BP$10,"#") -> #NAME? | BR38: =BN38-BP38 -> #NAME?
A39: {OA=OA061} | B39: RU=G-REIMLUX | C39: ITA | D39: o/w Branch | E39: =_xll.GetCtData("CO-AMOUNT","CONS-AMOUNT",$A$1:$A$4,$A39:$B39,E$5:E$10,"#") -> #NAME? | G39: =_xll.GetCtData("CO-AMOUNT","CONS-AMOUNT",$A$1:$A$4,$A39:$B39,G$5:G$10,"#") -> #NAME? | I39: =E39-G39 -> #NAME? | K39: =_xll.GetCtData("CO-AMOUNT","CONS-AMOUNT",$A$1:$A$4,$A39:$B39,K$5:K$10,"#") -> #NAME? | M39: =_xll.GetCtData("CO-AMOUNT","CONS-AMOUNT",$A$1:$A$4,$A39:$B39,M$5:M$10,"#") -> #NAME? | O39: =K39-M39 -> #NAME? | Q39: =_xll.GetCtData("CO-AMOUNT","CONS-AMOUNT",$A$1:$A$4,$A39:$B39,Q$5:Q$10,"#") -> #NAME? | S39: =_xll.GetCtData("CO-AMOUNT","CONS-AMOUNT",$A$1:$A$4,$A39:$B39,S$5:S$10,"#") -> #NAME? | U39: =Q39-S39 -> #NAME? | W39: =_xll.GetCtData("CO-AMOUNT","CONS-AMOUNT",$A$1:$A$4,$A39:$B39,W$5:W$10,"#") -> #NAME? | Y39: =_xll.GetCtData("CO-AMOUNT","CONS-AMOUNT",$A$1:$A$4,$A39:$B39,Y$5:Y$10,"#") -> #NAME? | AA39: =W39-Y39 -> #NAME? | AC39: =_xll.GetCtData("CO-AMOUNT","CONS-AMOUNT",$A$1:$A$4,$A39:$B39,AC$5:AC$10,"#") -> #NAME? | AE39: =_xll.GetCtData("CO-AMOUNT","CONS-AMOUNT",$A$1:$A$4,$A39:$B39,AE$5:AE$10,"#") -> #NAME? | AG39: =AC39-AE39 -> #NAME? | AI39: =_xll.GetCtData("CO-AMOUNT","CONS-AMOUNT",$A$1:$A$4,$A39:$B39,AI$5:AI$10,"#") -> #NAME? | AK39: =_xll.GetCtData("CO-AMOUNT","CONS-AMOUNT",$A$1:$A$4,$A39:$B39,AK$5:AK$10,"#") -> #NAME? | AM39: =AI39-AK39 -> #NAME? | AO39: =_xll.GetCtData("CO-AMOUNT","CONS-AMOUNT",$A$1:$A$4,$A39:$B39,AO$5:AO$10,"#") -> #NAME? | AQ39: =_xll.GetCtData("CO-AMOUNT","CONS-AMOUNT",$A$1:$A$4,$A39:$B39,AQ$5:AQ$10,"#") -> #NAME? | AS39: =AO39-AQ39 -> #NAME? | AU39: =W39+AC39+AI39+AO39 -> #NAME? | AW39: =Y39+AE39+AK39+AQ39 -> #NAME? | AY39: =AU39-AW39 -> #NAME? | BA39: =+Q39-AO39 -> #NAME? | BC39: =+S39-AQ39 -> #NAME? | BE39: =BA39-BC39 -> #NAME? | BG39: =_xll.GetCtData("CO-AMOUNT","CONS-AMOUNT",$A$1:$A$4,$A39:$B39,BG$5:BG$10,"#") -> #NAME? | BI39: =_xll.GetCtData("CO-AMOUNT","CONS-AMOUNT",$A$1:$A$4,$A39:$B39,BI$5:BI$10,"#") -> #NAME? | BK39: =BG39-BI39 -> #NAME? | BN39: =_xll.GetCtData("CO-AMOUNT","CONS-AMOUNT",$A$1:$A$4,$A39:$B39,BN$5:BN$10,"#") -> #NAME? | BP39: =_xll.GetCtData("CO-AMOUNT","CONS-AMOUNT",$A$1:$A$4,$A39:$B39,BP$5:BP$10,"#") -> #NAME? | BR39: =BN39-BP39 -> #NAME?
A40: {OA=OA060}+{OA=OA060E}+{OA=OA060O} | B40: RU sum AF026 | C40: ITA | D40: o/w REIM Italy | E40: =_xll.GetCtData("CO-AMOUNT","CONS-AMOUNT",$A$1:$A$4,$A40:$B40,E$5:E$10,"#") -> #NAME? | G40: =_xll.GetCtData("CO-AMOUNT","CONS-AMOUNT",$A$1:$A$4,$A40:$B40,G$5:G$10,"#") -> #NAME? | I40: =E40-G40 -> #NAME? | K40: =_xll.GetCtData("CO-AMOUNT","CONS-AMOUNT",$A$1:$A$4,$A40:$B40,K$5:K$10,"#-2,00000000001666E-03") -> #NAME? | M40: =_xll.GetCtData("CO-AMOUNT","CONS-AMOUNT",$A$1:$A$4,$A40:$B40,M$5:M$10,"#0,12700000000001") -> #NAME? | O40: =K40-M40 -> #NAME? | Q40: =_xll.GetCtData("CO-AMOUNT","CONS-AMOUNT",$A$1:$A$4,$A40:$B40,Q$5:Q$10,"#-2,00000000001799E-03") -> #NAME? | S40: =_xll.GetCtData("CO-AMOUNT","CONS-AMOUNT",$A$1:$A$4,$A40:$B40,S$5:S$10,"#0,12700000000001") -> #NAME? | U40: =Q40-S40 -> #NAME?
C41: ITA | D41: o/w Italy | E41: =E39+E40 -> #NAME? | G41: =G39+G40 -> #NAME? | I41: =E41-G41 -> #NAME? | K41: =K39+K40 -> #NAME? | M41: =M39+M40 -> #NAME? | O41: =K41-M41 -> #NAME? | Q41: =Q39+Q40 -> #NAME? | S41: =S39+S40 -> #NAME? | U41: =Q41-S41 -> #NAME?
A42: {OA=OA060}+{OA=OA060E}+{OA=OA060O} | B42: RU=G-REIMLUX | C42: LUX | D42: =CHOOSE([6]Traduction!$A$2,[6]Traduction!$A53,[6]Traduction!$B53) -> o/w Luxembourg | E42: =_xll.GetCtData("CO-AMOUNT","CONS-AMOUNT",$A$1:$A$4,$A42:$B42,E$5:E$10,"#") -> #NAME? | G42: =_xll.GetCtData("CO-AMOUNT","CONS-AMOUNT",$A$1:$A$4,$A42:$B42,G$5:G$10,"#") -> #NAME? | I42: =E42-G42 -> #NAME? | K42: =_xll.GetCtData("CO-AMOUNT","CONS-AMOUNT",$A$1:$A$4,$A42:$B42,K$5:K$10,"#") -> #NAME? | M42: =_xll.GetCtData("CO-AMOUNT","CONS-AMOUNT",$A$1:$A$4,$A42:$B42,M$5:M$10,"#") -> #NAME? | O42: =K42-M42 -> #NAME? | Q42: =_xll.GetCtData("CO-AMOUNT","CONS-AMOUNT",$A$1:$A$4,$A42:$B42,Q$5:Q$10,"#") -> #NAME? | S42: =_xll.GetCtData("CO-AMOUNT","CONS-AMOUNT",$A$1:$A$4,$A42:$B42,S$5:S$10,"#") -> #NAME? | U42: =Q42-S42 -> #NAME? | W42: =_xll.GetCtData("CO-AMOUNT","CONS-AMOUNT",$A$1:$A$4,$A42:$B42,W$5:W$10,"#") -> #NAME? | Y42: =_xll.GetCtData("CO-AMOUNT","CONS-AMOUNT",$A$1:$A$4,$A42:$B42,Y$5:Y$10,"#") -> #NAME? | AA42: =W42-Y42 -> #NAME? | AC42: =_xll.GetCtData("CO-AMOUNT","CONS-AMOUNT",$A$1:$A$4,$A42:$B42,AC$5:AC$10,"#") -> #NAME? | AE42: =_xll.GetCtData("CO-AMOUNT","CONS-AMOUNT",$A$1:$A$4,$A42:$B42,AE$5:AE$10,"#") -> #NAME? | AG42: =AC42-AE42 -> #NAME? | AI42: =_xll.GetCtData("CO-AMOUNT","CONS-AMOUNT",$A$1:$A$4,$A42:$B42,AI$5:AI$10,"#") -> #NAME? | AK42: =_xll.GetCtData("CO-AMOUNT","CONS-AMOUNT",$A$1:$A$4,$A42:$B42,AK$5:AK$10,"#") -> #NAME? | AM42: =AI42-AK42 -> #NAME? | AO42: =_xll.GetCtData("CO-AMOUNT","CONS-AMOUNT",$A$1:$A$4,$A42:$B42,AO$5:AO$10,"#") -> #NAME? | AQ42: =_xll.GetCtData("CO-AMOUNT","CONS-AMOUNT",$A$1:$A$4,$A42:$B42,AQ$5:AQ$10,"#") -> #NAME? | AS42: =AO42-AQ42 -> #NAME? | AU42: =W42+AC42+AI42+AO42 -> #NAME? | AW42: =Y42+AE42+AK42+AQ42 -> #NAME? | AY42: =AU42-AW42 -> #NAME? | BA42: =+Q42-AO42 -> #NAME? | BC42: =+S42-AQ42 -> #NAME? | BE42: =BA42-BC42 -> #NAME? | BG42: =_xll.GetCtData("CO-AMOUNT","CONS-AMOUNT",$A$1:$A$4,$A42:$B42,BG$5:BG$10,"#") -> #NAME? | BI42: =_xll.GetCtData("CO-AMOUNT","CONS-AMOUNT",$A$1:$A$4,$A42:$B42,BI$5:BI$10,"#") -> #NAME? | BK42: =BG42-BI42 -> #NAME? | BN42: =_xll.GetCtData("CO-AMOUNT","CONS-AMOUNT",$A$1:$A$4,$A42:$B42,BN$5:BN$10,"#") -> #NAME? | BP42: =_xll.GetCtData("CO-AMOUNT","CONS-AMOUNT",$A$1:$A$4,$A42:$B42,BP$5:BP$10,"#") -> #NAME? | BR42: =BN42-BP42 -> #NAME?
...

Sheet Réalisé Vs Estimé (Valeurs)
A1: SC=BNPPI-GEST
A2: CC=EUR
A3: FA sum AR002
A4: FL=F99 | E4: {AC=GFB001}+{AC=GFB002}+{AC=GFB004}+{AC=GFB008}+{AC=GFB009}+{AC=GFB003} | G4: {AC=GFB001}+{AC=GFB002}+{AC=GFB004}+{AC=GFB008}+{AC=GFB009}+{AC=GFB003} | K4: {AC=GFB005}+{AC=GFB006}+{AC=GFB110}+{AC=GFB111}+{AC=GFB112}+{AC=GFB120}+{AC=GFB121}+{AC=GFB122}+{AC=GFB100}+{AC=GFB101}+{AC=GFB102}+{AC=GFB130}+{AC=GFB131}+{AC=GFB132} | M4: {AC=GFB005}+{AC=GFB006}+{AC=GFB110}+{AC=GFB111}+{AC=GFB112}+{AC=GFB120}+{AC=GFB121}+{AC=GFB122}+{AC=GFB100}+{AC=GFB101}+{AC=GFB102}+{AC=GFB130}+{AC=GFB131}+{AC=GFB132} | Q4: AC sum RGFB | S4: AC sum RGFB | W4: AC sum RGFB | Y4: AC sum RGFB | AC4: AC sum RGFB | AE4: AC sum RGFB | AI4: AC sum RGFB | AK4: AC sum RGFB | AO4: AC sum RGFB | AQ4: AC sum RGFB | BA4: AC sum RGFB | BB4: AC sum RGFB | BC4: AC sum RGFB | BG4: AC sum RGFB | BI4: AC sum RGFB | BN4: AC sum RGFB | BO4: 0 | BP4: AC sum RGFB
E5: CA=A | G5: CA=E | K5: CA=A | L5: CA=A | M5: CA=E | N5: CA=E | Q5: CA=A | R5: CA=A | S5: CA=E | T5: CA=E | W5: CA=A | X5: CA=A | Y5: CA=E | Z5: CA=E | AC5: CA=A | AD5: CA=A | AE5: CA=E | AF5: CA=E | AI5: CA=A | AJ5: CA=A | AK5: CA=E | AL5: CA=E | AO5: CA=A | AP5: CA=A | AQ5: CA=E | AR5: CA=E | BA5: CA=A | BB5: CA=A | BC5: CA=E | BD5: CA=E | BG5: CA=A | BH5: CA=A | BI5: CA=E | BJ5: CA=E | BN5: CA=A | BO5: CA=A | BP5: CA=E | BQ5: CA=E
